Workbook

Sheet Sum
A1: Item Code | B1: Product Name | C1: 46125 | D1: Purchased | E1: Arrived | F1: Sales Order | G1: Cons. | H1: OH Stock | I1: In-Transit | J1: On Hold | K1: Alloc. | L1: Avail. | M1: Total Stock | N1: ABC | O1: Wkly Fcst. | P1: OH TO | Q1: Inv. TO | R1: LT | S1: SS | T1: Extra | U1: MOQ | V1: Plan | W1: LA Plan | X1: HOU Plan | Y1: Case Pack | Z1: Channel | AA1: Case Type | AB1: Case Qty | AC1: CBM
A2: BOBO22-GN | B2: =_xlfn.XLOOKUP(A2,'Product List'!B:B,'Product List'!I:I) -> MINI/MOE SILENT CRSTL RUN WHEEL LG 8.5-Green | C2: 0 | D2: =SUMIFS(Purchase!F:F,Purchase!C:C,A2,Purchase!I:I,">"&$C$1,Purchase!V:V,"<>暂缓发货") -> 744 | E2: =SUMIFS(Purchase!F:F,Purchase!C:C,A2,Purchase!J:J,">0",Purchase!I:I,">"&$C$1) -> 744 | F2: =SUMIFS(Sales!E:E,Sales!C:C,A2,Sales!K:K,">"&$C$1) -> 376 | G2: =SUMIFS(Sales!E:E,Sales!C:C,A2,Sales!K:K,">"&$C$1,Sales!L:L,">0") -> 368 | H2: =C2+E2-G2-SUMIFS(Transfer!V:V,Transfer!O:O,A2)+SUMIFS(Transfer!W:W,Transfer!O:O,A2) -> 376 | I2: =D2-E2+SUMIFS(Transfer!V:V,Transfer!O:O,A2)-SUMIFS(Transfer!W:W,Transfer!O:O,A2) -> 0 | J2: =SUMIFS(Purchase!F:F,Purchase!C:C,A2,Purchase!V:V,"暂缓发货") -> 0 | K2: =F2-G2 -> 8 | L2: =H2-K2 -> 368 | M2: =H2+I2-K2 -> 368 | N2: =_xlfn.XLOOKUP(A2,'Product List'!B:B,'Product List'!F:F) -> C | O2: =SUMIF('Weekly Sales'!B:B,A2,'Weekly Sales'!R:R) -> 12.666667 | P2: =IF(O2=0,999,ROUNDDOWN((L2)/O2,0)) -> 29 | Q2: =IF(O2=0,999,ROUNDDOWN((M2)/O2,0)) -> 29 | R2: =_xlfn.XLOOKUP(A2,'Product List'!B:B,'Product List'!P:P) -> 10 | S2: =IF(N2="A",6,IF(N2="B",5,2)) -> 2 | T2: =SUMIF('Weekly Sales'!B:B,A2,'Weekly Sales'!T:T) -> 0 | U2: =_xlfn.XLOOKUP(A2,'Product List'!B:B,'Product List'!O:O) -> 1000 | V2: =ROUNDUP(MAX(0,O2*(R2+S2+2)+T2-M2)/Y2,0)*Y2 -> 0 | W2: =_xlfn.XLOOKUP(A2,Sum_LA!A:A,Sum_LA!V:V) -> 0 | X2: =_xlfn.XLOOKUP(A2,Sum_HOU!A:A,Sum_HOU!V:V) -> 192 | Y2: {=_xlfn.XLOOKUP(1,('Case Pack'!A:A=A2)*('Case Pack'!F:F<=TODAY()),'Case Pack'!D:D,"未找到箱规")} -> 16 | Z2: =_xlfn.XLOOKUP(A2,'Product List'!B:B,'Product List'!M:M) -> PSP | AA2: {=_xlfn.XLOOKUP(1,('Case Pack'!A:A=A2)*('Case Pack'!F:F<=TODAY()),'Case Pack'!G:G,"未找到箱规")} -> C | AB2: =V2/Y2 -> 0 | AC2: =_xlfn.XLOOKUP(AA2,'Case Type'!A:A,'Case Type'!H:H)*AB2 -> 0
A3: BOBO22-WH | B3: =_xlfn.XLOOKUP(A3,'Product List'!B:B,'Product List'!I:I) -> MINI/MOE SILENT CRSTL RUN WHEEL LG 8.5-White | C3: 412 | D3: =SUMIFS(Purchase!F:F,Purchase!C:C,A3,Purchase!I:I,">"&$C$1,Purchase!V:V,"<>暂缓发货") -> 7336 | E3: =SUMIFS(Purchase!F:F,Purchase!C:C,A3,Purchase!J:J,">0",Purchase!I:I,">"&$C$1) -> 7336 | F3: =SUMIFS(Sales!E:E,Sales!C:C,A3,Sales!K:K,">"&$C$1) -> 4748 | G3: =SUMIFS(Sales!E:E,Sales!C:C,A3,Sales!K:K,">"&$C$1,Sales!L:L,">0") -> 3876 | H3: =C3+E3-G3-SUMIFS(Transfer!V:V,Transfer!O:O,A3)+SUMIFS(Transfer!W:W,Transfer!O:O,A3) -> 3872 | I3: =D3-E3+SUMIFS(Transfer!V:V,Transfer!O:O,A3)-SUMIFS(Transfer!W:W,Transfer!O:O,A3) -> 0 | J3: =SUMIFS(Purchase!F:F,Purchase!C:C,A3,Purchase!V:V,"暂缓发货") -> 1352 | K3: =F3-G3 -> 872 | L3: =H3-K3 -> 3000 | M3: =H3+I3-K3 -> 3000 | N3: =_xlfn.XLOOKUP(A3,'Product List'!B:B,'Product List'!F:F) -> A | O3: =SUMIF('Weekly Sales'!B:B,A3,'Weekly Sales'!R:R) -> 95.5 | P3: =IF(O3=0,999,ROUNDDOWN((L3)/O3,0)) -> 31 | Q3: =IF(O3=0,999,ROUNDDOWN((M3)/O3,0)) -> 31 | R3: =_xlfn.XLOOKUP(A3,'Product List'!B:B,'Product List'!P:P) -> 10 | S3: =IF(N3="A",6,IF(N3="B",5,2)) -> 6 | T3: =SUMIF('Weekly Sales'!B:B,A3,'Weekly Sales'!T:T) -> 620.75 | U3: =_xlfn.XLOOKUP(A3,'Product List'!B:B,'Product List'!O:O) -> 1000 | V3: =ROUNDUP(MAX(0,O3*(R3+S3+2)+T3-M3)/Y3,0)*Y3 -> 0 | W3: =_xlfn.XLOOKUP(A3,Sum_LA!A:A,Sum_LA!V:V) -> 0 | X3: =_xlfn.XLOOKUP(A3,Sum_HOU!A:A,Sum_HOU!V:V) -> 0 | Y3: {=_xlfn.XLOOKUP(1,('Case Pack'!A:A=A3)*('Case Pack'!F:F<=TODAY()),'Case Pack'!D:D,"未找到箱规")} -> 16 | Z3: =_xlfn.XLOOKUP(A3,'Product List'!B:B,'Product List'!M:M) -> PetcoUS, PetcoMX, Pet Supermarket，PSP | AA3: {=_xlfn.XLOOKUP(1,('Case Pack'!A:A=A3)*('Case Pack'!F:F<=TODAY()),'Case Pack'!G:G,"未找到箱规")} -> C | AB3: =V3/Y3 -> 0 | AC3: =_xlfn.XLOOKUP(AA3,'Case Type'!A:A,'Case Type'!H:H)*AB3 -> 0
A4: CFDL1090-BR | B4: =_xlfn.XLOOKUP(A4,'Product List'!B:B,'Product List'!I:I) -> MINI/MOE SMALL ANIMAL BEDDING CRINKLE PAPER BROWN 1EA | C4: 0 | D4: =SUMIFS(Purchase!F:F,Purchase!C:C,A4,Purchase!I:I,">"&$C$1,Purchase!V:V,"<>暂缓发货") -> 1260 | E4: =SUMIFS(Purchase!F:F,Purchase!C:C,A4,Purchase!J:J,">0",Purchase!I:I,">"&$C$1) -> 1260 | F4: =SUMIFS(Sales!E:E,Sales!C:C,A4,Sales!K:K,">"&$C$1) -> 630 | G4: =SUMIFS(Sales!E:E,Sales!C:C,A4,Sales!K:K,">"&$C$1,Sales!L:L,">0") -> 630 | H4: =C4+E4-G4-SUMIFS(Transfer!V:V,Transfer!O:O,A4)+SUMIFS(Transfer!W:W,Transfer!O:O,A4) -> 630 | I4: =D4-E4+SUMIFS(Transfer!V:V,Transfer!O:O,A4)-SUMIFS(Transfer!W:W,Transfer!O:O,A4) -> 0 | J4: =SUMIFS(Purchase!F:F,Purchase!C:C,A4,Purchase!V:V,"暂缓发货") -> 0 | K4: =F4-G4 -> 0 | L4: =H4-K4 -> 630 | M4: =H4+I4-K4 -> 630 | N4: =_xlfn.XLOOKUP(A4,'Product List'!B:B,'Product List'!F:F) -> C | O4: =SUMIF('Weekly Sales'!B:B,A4,'Weekly Sales'!R:R) -> 6 | P4: =IF(O4=0,999,ROUNDDOWN((L4)/O4,0)) -> 105 | Q4: =IF(O4=0,999,ROUNDDOWN((M4)/O4,0)) -> 105 | R4: =_xlfn.XLOOKUP(A4,'Product List'!B:B,'Product List'!P:P) -> 10 | S4: =IF(N4="A",6,IF(N4="B",5,2)) -> 2 | T4: =SUMIF('Weekly Sales'!B:B,A4,'Weekly Sales'!T:T) -> 0 | U4: =_xlfn.XLOOKUP(A4,'Product List'!B:B,'Product List'!O:O) -> 1000 | V4: =ROUNDUP(MAX(0,O4*(R4+S4+2)+T4-M4)/Y4,0)*Y4 -> 0 | W4: =_xlfn.XLOOKUP(A4,Sum_LA!A:A,Sum_LA!V:V) -> 0 | X4: =_xlfn.XLOOKUP(A4,Sum_HOU!A:A,Sum_HOU!V:V) -> 90 | Y4: {=_xlfn.XLOOKUP(1,('Case Pack'!A:A=A4)*('Case Pack'!F:F<=TODAY()),'Case Pack'!D:D,"未找到箱规")} -> 30 | Z4: =_xlfn.XLOOKUP(A4,'Product List'!B:B,'Product List'!M:M) -> PSP | AA4: {=_xlfn.XLOOKUP(1,('Case Pack'!A:A=A4)*('Case Pack'!F:F<=TODAY()),'Case Pack'!G:G,"未找到箱规")} -> A | AB4: =V4/Y4 -> 0 | AC4: =_xlfn.XLOOKUP(AA4,'Case Type'!A:A,'Case Type'!H:H)*AB4 -> 0
A5: CFDL1090-PK | B5: =_xlfn.XLOOKUP(A5,'Product List'!B:B,'Product List'!I:I) -> MINI/MOE SMALL ANIMAL BEDDING PAPER PEBBLES PSTCH/CREAM 1EA | C5: 0 | D5: =SUMIFS(Purchase!F:F,Purchase!C:C,A5,Purchase!I:I,">"&$C$1,Purchase!V:V,"<>暂缓发货") -> 1260 | E5: =SUMIFS(Purchase!F:F,Purchase!C:C,A5,Purchase!J:J,">0",Purchase!I:I,">"&$C$1) -> 1260 | F5: =SUMIFS(Sales!E:E,Sales!C:C,A5,Sales!K:K,">"&$C$1) -> 630 | G5: =SUMIFS(Sales!E:E,Sales!C:C,A5,Sales!K:K,">"&$C$1,Sales!L:L,">0") -> 630 | H5: =C5+E5-G5-SUMIFS(Transfer!V:V,Transfer!O:O,A5)+SUMIFS(Transfer!W:W,Transfer!O:O,A5) -> 630 | I5: =D5-E5+SUMIFS(Transfer!V:V,Transfer!O:O,A5)-SUMIFS(Transfer!W:W,Transfer!O:O,A5) -> 0 | J5: =SUMIFS(Purchase!F:F,Purchase!C:C,A5,Purchase!V:V,"暂缓发货") -> 0 | K5: =F5-G5 -> 0 | L5: =H5-K5 -> 630 | M5: =H5+I5-K5 -> 630 | N5: =_xlfn.XLOOKUP(A5,'Product List'!B:B,'Product List'!F:F) -> C | O5: =SUMIF('Weekly Sales'!B:B,A5,'Weekly Sales'!R:R) -> 1.3333333 | P5: =IF(O5=0,999,ROUNDDOWN((L5)/O5,0)) -> 472 | Q5: =IF(O5=0,999,ROUNDDOWN((M5)/O5,0)) -> 472 | R5: =_xlfn.XLOOKUP(A5,'Product List'!B:B,'Product List'!P:P) -> 10 | S5: =IF(N5="A",6,IF(N5="B",5,2)) -> 2 | T5: =SUMIF('Weekly Sales'!B:B,A5,'Weekly Sales'!T:T) -> 0 | U5: =_xlfn.XLOOKUP(A5,'Product List'!B:B,'Product List'!O:O) -> 1000 | V5: =ROUNDUP(MAX(0,O5*(R5+S5+2)+T5-M5)/Y5,0)*Y5 -> 0 | W5: =_xlfn.XLOOKUP(A5,Sum_LA!A:A,Sum_LA!V:V) -> 0 | X5: =_xlfn.XLOOKUP(A5,Sum_HOU!A:A,Sum_HOU!V:V) -> 30 | Y5: {=_xlfn.XLOOKUP(1,('Case Pack'!A:A=A5)*('Case Pack'!F:F<=TODAY()),'Case Pack'!D:D,"未找到箱规")} -> 30 | Z5: =_xlfn.XLOOKUP(A5,'Product List'!B:B,'Product List'!M:M) -> PSP | AA5: {=_xlfn.XLOOKUP(1,('Case Pack'!A:A=A5)*('Case Pack'!F:F<=TODAY()),'Case Pack'!G:G,"未找到箱规")} -> A | AB5: =V5/Y5 -> 0 | AC5: =_xlfn.XLOOKUP(AA5,'Case Type'!A:A,'Case Type'!H:H)*AB5 -> 0
A6: CFDL9000-GN-YL | B6: =_xlfn.XLOOKUP(A6,'Product List'!B:B,'Product List'!I:I) -> MINI/MOE SMALL ANIMAL BEDDING ROLLED PAPER FOREST MIX 1EA | C6: 0 | D6: =SUMIFS(Purchase!F:F,Purchase!C:C,A6,Purchase!I:I,">"&$C$1,Purchase!V:V,"<>暂缓发货") -> 3420 | E6: =SUMIFS(Purchase!F:F,Purchase!C:C,A6,Purchase!J:J,">0",Purchase!I:I,">"&$C$1) -> 3420 | F6: =SUMIFS(Sales!E:E,Sales!C:C,A6,Sales!K:K,">"&$C$1) -> 2040 | G6: =SUMIFS(Sales!E:E,Sales!C:C,A6,Sales!K:K,">"&$C$1,Sales!L:L,">0") -> 2040 | H6: =C6+E6-G6-SUMIFS(Transfer!V:V,Transfer!O:O,A6)+SUMIFS(Transfer!W:W,Transfer!O:O,A6) -> 1380 | I6: =D6-E6+SUMIFS(Transfer!V:V,Transfer!O:O,A6)-SUMIFS(Transfer!W:W,Transfer!O:O,A6) -> 0 | J6: =SUMIFS(Purchase!F:F,Purchase!C:C,A6,Purchase!V:V,"暂缓发货") -> 0 | K6: =F6-G6 -> 0 | L6: =H6-K6 -> 1380 | M6: =H6+I6-K6 -> 1380 | N6: =_xlfn.XLOOKUP(A6,'Product List'!B:B,'Product List'!F:F) -> B | O6: =SUMIF('Weekly Sales'!B:B,A6,'Weekly Sales'!R:R) -> 4 | P6: =IF(O6=0,999,ROUNDDOWN((L6)/O6,0)) -> 345 | Q6: =IF(O6=0,999,ROUNDDOWN((M6)/O6,0)) -> 345 | R6: =_xlfn.XLOOKUP(A6,'Product List'!B:B,'Product List'!P:P) -> 10 | S6: =IF(N6="A",6,IF(N6="B",5,2)) -> 5 | T6: =SUMIF('Weekly Sales'!B:B,A6,'Weekly Sales'!T:T) -> 21 | U6: =_xlfn.XLOOKUP(A6,'Product List'!B:B,'Product List'!O:O) -> 1000 | V6: =ROUNDUP(MAX(0,O6*(R6+S6+2)+T6-M6)/Y6,0)*Y6 -> 0 | W6: =_xlfn.XLOOKUP(A6,Sum_LA!A:A,Sum_LA!V:V) -> 0 | X6: =_xlfn.XLOOKUP(A6,Sum_HOU!A:A,Sum_HOU!V:V) -> 90 | Y6: {=_xlfn.XLOOKUP(1,('Case Pack'!A:A=A6)*('Case Pack'!F:F<=TODAY()),'Case Pack'!D:D,"未找到箱规")} -> 30 | Z6: =_xlfn.XLOOKUP(A6,'Product List'!B:B,'Product List'!M:M) -> PSP | AA6: {=_xlfn.XLOOKUP(1,('Case Pack'!A:A=A6)*('Case Pack'!F:F<=TODAY()),'Case Pack'!G:G,"未找到箱规")} -> A | AB6: =V6/Y6 -> 0 | AC6: =_xlfn.XLOOKUP(AA6,'Case Type'!A:A,'Case Type'!H:H)*AB6 -> 0
A7: CFLS18000 | B7: =_xlfn.XLOOKUP(A7,'Product List'!B:B,'Product List'!I:I) -> MMO-GREEN APPLE CHEW | C7: 0 | D7: =SUMIFS(Purchase!F:F,Purchase!C:C,A7,Purchase!I:I,">"&$C$1,Purchase!V:V,"<>暂缓发货") -> 9936 | E7: =SUMIFS(Purchase!F:F,Purchase!C:C,A7,Purchase!J:J,">0",Purchase!I:I,">"&$C$1) -> 9936 | F7: =SUMIFS(Sales!E:E,Sales!C:C,A7,Sales!K:K,">"&$C$1) -> 5568 | G7: =SUMIFS(Sales!E:E,Sales!C:C,A7,Sales!K:K,">"&$C$1,Sales!L:L,">0") -> 4560 | H7: =C7+E7-G7-SUMIFS(Transfer!V:V,Transfer!O:O,A7)+SUMIFS(Transfer!W:W,Transfer!O:O,A7) -> 5376 | I7: =D7-E7+SUMIFS(Transfer!V:V,Transfer!O:O,A7)-SUMIFS(Transfer!W:W,Transfer!O:O,A7) -> 0 | J7: =SUMIFS(Purchase!F:F,Purchase!C:C,A7,Purchase!V:V,"暂缓发货") -> 2112 | K7: =F7-G7 -> 1008 | L7: =H7-K7 -> 4368 | M7: =H7+I7-K7 -> 4368 | N7: =_xlfn.XLOOKUP(A7,'Product List'!B:B,'Product List'!F:F) -> B | O7: =SUMIF('Weekly Sales'!B:B,A7,'Weekly Sales'!R:R) -> 150.16667 | P7: =IF(O7=0,999,ROUNDDOWN((L7)/O7,0)) -> 29 | Q7: =IF(O7=0,999,ROUNDDOWN((M7)/O7,0)) -> 29 | R7: =_xlfn.XLOOKUP(A7,'Product List'!B:B,'Product List'!P:P) -> 10 | S7: =IF(N7="A",6,IF(N7="B",5,2)) -> 5 | T7: =SUMIF('Weekly Sales'!B:B,A7,'Weekly Sales'!T:T) -> 498.70833 | U7: =_xlfn.XLOOKUP(A7,'Product List'!B:B,'Product List'!O:O) -> 1000 | V7: =ROUNDUP(MAX(0,O7*(R7+S7+2)+T7-M7)/Y7,0)*Y7 -> 0 | W7: =_xlfn.XLOOKUP(A7,Sum_LA!A:A,Sum_LA!V:V) -> 0 | X7: =_xlfn.XLOOKUP(A7,Sum_HOU!A:A,Sum_HOU!V:V) -> 144 | Y7: {=_xlfn.XLOOKUP(1,('Case Pack'!A:A=A7)*('Case Pack'!F:F<=TODAY()),'Case Pack'!D:D,"未找到箱规")} -> 48 | Z7: =_xlfn.XLOOKUP(A7,'Product List'!B:B,'Product List'!M:M) -> PetcoUS，PSP | AA7: {=_xlfn.XLOOKUP(1,('Case Pack'!A:A=A7)*('Case Pack'!F:F<=TODAY()),'Case Pack'!G:G,"未找到箱规")} -> B | AB7: =V7/Y7 -> 0 | AC7: =_xlfn.XLOOKUP(AA7,'Case Type'!A:A,'Case Type'!H:H)*AB7 -> 0
A8: CFLS64000YE | B8: =_xlfn.XLOOKUP(A8,'Product List'!B:B,'Product List'!I:I) -> MMO-CAMP LUNCH BOX CHEW | C8: 0 | D8: =SUMIFS(Purchase!F:F,Purchase!C:C,A8,Purchase!I:I,">"&$C$1,Purchase!V:V,"<>暂缓发货") -> 10800 | E8: =SUMIFS(Purchase!F:F,Purchase!C:C,A8,Purchase!J:J,">0",Purchase!I:I,">"&$C$1) -> 10800 | F8: =SUMIFS(Sales!E:E,Sales!C:C,A8,Sales!K:K,">"&$C$1) -> 6768 | G8: =SUMIFS(Sales!E:E,Sales!C:C,A8,Sales!K:K,">"&$C$1,Sales!L:L,">0") -> 5616 | H8: =C8+E8-G8-SUMIFS(Transfer!V:V,Transfer!O:O,A8)+SUMIFS(Transfer!W:W,Transfer!O:O,A8) -> 5184 | I8: =D8-E8+SUMIFS(Transfer!V:V,Transfer!O:O,A8)-SUMIFS(Transfer!W:W,Transfer!O:O,A8) -> 0 | J8: =SUMIFS(Purchase!F:F,Purchase!C:C,A8,Purchase!V:V,"暂缓发货") -> 2160 | K8: =F8-G8 -> 1152 | L8: =H8-K8 -> 4032 | M8: =H8+I8-K8 -> 4032 | N8: =_xlfn.XLOOKUP(A8,'Product List'!B:B,'Product List'!F:F) -> B | O8: =SUMIF('Weekly Sales'!B:B,A8,'Weekly Sales'!R:R) -> 167.83333 | P8: =IF(O8=0,999,ROUNDDOWN((L8)/O8,0)) -> 24 | Q8: =IF(O8=0,999,ROUNDDOWN((M8)/O8,0)) -> 24 | R8: =_xlfn.XLOOKUP(A8,'Product List'!B:B,'Product List'!P:P) -> 10 | S8: =IF(N8="A",6,IF(N8="B",5,2)) -> 5 | T8: =SUMIF('Weekly Sales'!B:B,A8,'Weekly Sales'!T:T) -> 560.45833 | U8: =_xlfn.XLOOKUP(A8,'Product List'!B:B,'Product List'!O:O) -> 1000 | V8: =ROUNDUP(MAX(0,O8*(R8+S8+2)+T8-M8)/Y8,0)*Y8 -> 0 | W8: =_xlfn.XLOOKUP(A8,Sum_LA!A:A,Sum_LA!V:V) -> 0 | X8: =_xlfn.XLOOKUP(A8,Sum_HOU!A:A,Sum_HOU!V:V) -> 216 | Y8: {=_xlfn.XLOOKUP(1,('Case Pack'!A:A=A8)*('Case Pack'!F:F<=TODAY()),'Case Pack'!D:D,"未找到箱规")} -> 72 | Z8: =_xlfn.XLOOKUP(A8,'Product List'!B:B,'Product List'!M:M) -> PetcoUS, Pet Supermarket，PSP | AA8: {=_xlfn.XLOOKUP(1,('Case Pack'!A:A=A8)*('Case Pack'!F:F<=TODAY()),'Case Pack'!G:G,"未找到箱规")} -> B | AB8: =V8/Y8 -> 0 | AC8: =_xlfn.XLOOKUP(AA8,'Case Type'!A:A,'Case Type'!H:H)*AB8 -> 0
A9: CFLS71000WH | B9: =_xlfn.XLOOKUP(A9,'Product List'!B:B,'Product List'!I:I) -> MMO-SHELL PEARL HAMSTER CHEW | C9: 0 | D9: =SUMIFS(Purchase!F:F,Purchase!C:C,A9,Purchase!I:I,">"&$C$1,Purchase!V:V,"<>暂缓发货") -> 5248 | E9: =SUMIFS(Purchase!F:F,Purchase!C:C,A9,Purchase!J:J,">0",Purchase!I:I,">"&$C$1) -> 5248 | F9: =SUMIFS(Sales!E:E,Sales!C:C,A9,Sales!K:K,">"&$C$1) -> 2112 | G9: =SUMIFS(Sales!E:E,Sales!C:C,A9,Sales!K:K,">"&$C$1,Sales!L:L,">0") -> 2112 | H9: =C9+E9-G9-SUMIFS(Transfer!V:V,Transfer!O:O,A9)+SUMIFS(Transfer!W:W,Transfer!O:O,A9) -> 3136 | I9: =D9-E9+SUMIFS(Transfer!V:V,Transfer!O:O,A9)-SUMIFS(Transfer!W:W,Transfer!O:O,A9) -> 0 | J9: =SUMIFS(Purchase!F:F,Purchase!C:C,A9,Purchase!V:V,"暂缓发货") -> 640 | K9: =F9-G9 -> 0 | L9: =H9-K9 -> 3136 | M9: =H9+I9-K9 -> 3136 | N9: =_xlfn.XLOOKUP(A9,'Product List'!B:B,'Product List'!F:F) -> C | O9: =SUMIF('Weekly Sales'!B:B,A9,'Weekly Sales'!R:R) -> 31.166667 | P9: =IF(O9=0,999,ROUNDDOWN((L9)/O9,0)) -> 100 | Q9: =IF(O9=0,999,ROUNDDOWN((M9)/O9,0)) -> 100 | R9: =_xlfn.XLOOKUP(A9,'Product List'!B:B,'Product List'!P:P) -> 10 | S9: =IF(N9="A",6,IF(N9="B",5,2)) -> 2 | T9: =SUMIF('Weekly Sales'!B:B,A9,'Weekly Sales'!T:T) -> 0 | U9: =_xlfn.XLOOKUP(A9,'Product List'!B:B,'Product List'!O:O) -> 1000 | V9: =ROUNDUP(MAX(0,O9*(R9+S9+2)+T9-M9)/Y9,0)*Y9 -> 0 | W9: =_xlfn.XLOOKUP(A9,Sum_LA!A:A,Sum_LA!V:V) -> 0 | X9: =_xlfn.XLOOKUP(A9,Sum_HOU!A:A,Sum_HOU!V:V) -> 0 | Y9: {=_xlfn.XLOOKUP(1,('Case Pack'!A:A=A9)*('Case Pack'!F:F<=TODAY()),'Case Pack'!D:D,"未找到箱规")} -> 64 | Z9: =_xlfn.XLOOKUP(A9,'Product List'!B:B,'Product List'!M:M) -> PetcoUS | AA9: {=_xlfn.XLOOKUP(1,('Case Pack'!A:A=A9)*('Case Pack'!F:F<=TODAY()),'Case Pack'!G:G,"未找到箱规")} -> B | AB9: =V9/Y9 -> 0 | AC9: =_xlfn.XLOOKUP(AA9,'Case Type'!A:A,'Case Type'!H:H)*AB9 -> 0
A10: CPSH54000WH | B10: =_xlfn.XLOOKUP(A10,'Product List'!B:B,'Product List'!I:I) -> NONO Magnetic Water Bottle (220 ML) | C10: 0 | D10: =SUMIFS(Purchase!F:F,Purchase!C:C,A10,Purchase!I:I,">"&$C$1,Purchase!V:V,"<>暂缓发货") -> 1260 | E10: =SUMIFS(Purchase!F:F,Purchase!C:C,A10,Purchase!J:J,">0",Purchase!I:I,">"&$C$1) -> 1260 | F10: =SUMIFS(Sales!E:E,Sales!C:C,A10,Sales!K:K,">"&$C$1) -> 660 | G10: =SUMIFS(Sales!E:E,Sales!C:C,A10,Sales!K:K,">"&$C$1,Sales!L:L,">0") -> 660 | H10: =C10+E10-G10-SUMIFS(Transfer!V:V,Transfer!O:O,A10)+SUMIFS(Transfer!W:W,Transfer!O:O,A10) -> 600 | I10: =D10-E10+SUMIFS(Transfer!V:V,Transfer!O:O,A10)-SUMIFS(Transfer!W:W,Transfer!O:O,A10) -> 0 | J10: =SUMIFS(Purchase!F:F,Purchase!C:C,A10,Purchase!V:V,"暂缓发货") -> 0 | K10: =F10-G10 -> 0 | L10: =H10-K10 -> 600 | M10: =H10+I10-K10 -> 600 | N10: =_xlfn.XLOOKUP(A10,'Product List'!B:B,'Product List'!F:F) -> C | O10: =SUMIF('Weekly Sales'!B:B,A10,'Weekly Sales'!R:R) -> 7.6666667 | P10: =IF(O10=0,999,ROUNDDOWN((L10)/O10,0)) -> 78 | Q10: =IF(O10=0,999,ROUNDDOWN((M10)/O10,0)) -> 78 | R10: =_xlfn.XLOOKUP(A10,'Product List'!B:B,'Product List'!P:P) -> 10 | S10: =IF(N10="A",6,IF(N10="B",5,2)) -> 2 | T10: =SUMIF('Weekly Sales'!B:B,A10,'Weekly Sales'!T:T) -> 0 | U10: =_xlfn.XLOOKUP(A10,'Product List'!B:B,'Product List'!O:O) -> 500 | V10: =ROUNDUP(MAX(0,O10*(R10+S10+2)+T10-M10)/Y10,0)*Y10 -> 0 | W10: =_xlfn.XLOOKUP(A10,Sum_LA!A:A,Sum_LA!V:V) -> 0 | X10: =_xlfn.XLOOKUP(A10,Sum_HOU!A:A,Sum_HOU!V:V) -> 120 | Y10: {=_xlfn.XLOOKUP(1,('Case Pack'!A:A=A10)*('Case Pack'!F:F<=TODAY()),'Case Pack'!D:D,"未找到箱规")} -> 60 | Z10: =_xlfn.XLOOKUP(A10,'Product List'!B:B,'Product List'!M:M) -> PetcoMX,PSP | AA10: {=_xlfn.XLOOKUP(1,('Case Pack'!A:A=A10)*('Case Pack'!F:F<=TODAY()),'Case Pack'!G:G,"未找到箱规")} -> A | AB10: =V10/Y10 -> 0 | AC10: =_xlfn.XLOOKUP(AA10,'Case Type'!A:A,'Case Type'!H:H)*AB10 -> 0
A11: CPSH60007BK | B11: =_xlfn.XLOOKUP(A11,'Product List'!B:B,'Product List'!I:I) -> MINI & MOE MAG CONECT WTR BTL 4 OZ | C11: 0 | D11: =SUMIFS(Purchase!F:F,Purchase!C:C,A11,Purchase!I:I,">"&$C$1,Purchase!V:V,"<>暂缓发货") -> 15606 | E11: =SUMIFS(Purchase!F:F,Purchase!C:C,A11,Purchase!J:J,">0",Purchase!I:I,">"&$C$1) -> 15606 | F11: =SUMIFS(Sales!E:E,Sales!C:C,A11,Sales!K:K,">"&$C$1) -> 6912 | G11: =SUMIFS(Sales!E:E,Sales!C:C,A11,Sales!K:K,">"&$C$1,Sales!L:L,">0") -> 6912 | H11: =C11+E11-G11-SUMIFS(Transfer!V:V,Transfer!O:O,A11)+SUMIFS(Transfer!W:W,Transfer!O:O,A11) -> 8694 | I11: =D11-E11+SUMIFS(Transfer!V:V,Transfer!O:O,A11)-SUMIFS(Transfer!W:W,Transfer!O:O,A11) -> 0 | J11: =SUMIFS(Purchase!F:F,Purchase!C:C,A11,Purchase!V:V,"暂缓发货") -> 432 | K11: =F11-G11 -> 0 | L11: =H11-K11 -> 8694 | M11: =H11+I11-K11 -> 8694 | N11: =_xlfn.XLOOKUP(A11,'Product List'!B:B,'Product List'!F:F) -> A | O11: =SUMIF('Weekly Sales'!B:B,A11,'Weekly Sales'!R:R) -> 315 | P11: =IF(O11=0,999,ROUNDDOWN((L11)/O11,0)) -> 27 | Q11: =IF(O11=0,999,ROUNDDOWN((M11)/O11,0)) -> 27 | R11: =_xlfn.XLOOKUP(A11,'Product List'!B:B,'Product List'!P:P) -> 10 | S11: =IF(N11="A",6,IF(N11="B",5,2)) -> 6 | T11: =SUMIF('Weekly Sales'!B:B,A11,'Weekly Sales'!T:T) -> 2047.5 | U11: =_xlfn.XLOOKUP(A11,'Product List'!B:B,'Product List'!O:O) -> 500 | V11: =ROUNDUP(MAX(0,O11*(R11+S11+2)+T11-M11)/Y11,0)*Y11 -> 0 | W11: =_xlfn.XLOOKUP(A11,Sum_LA!A:A,Sum_LA!V:V) -> 0 | X11: =_xlfn.XLOOKUP(A11,Sum_HOU!A:A,Sum_HOU!V:V) -> 0 | Y11: {=_xlfn.XLOOKUP(1,('Case Pack'!A:A=A11)*('Case Pack'!F:F<=TODAY()),'Case Pack'!D:D,"未找到箱规")} -> 54 | Z11: =_xlfn.XLOOKUP(A11,'Product List'!B:B,'Product List'!M:M) -> Petsmart | AA11: {=_xlfn.XLOOKUP(1,('Case Pack'!A:A=A11)*('Case Pack'!F:F<=TODAY()),'Case Pack'!G:G,"未找到箱规")} -> A | AB11: =V11/Y11 -> 0 | AC11: =_xlfn.XLOOKUP(AA11,'Case Type'!A:A,'Case Type'!H:H)*AB11 -> 0
A12: CPSL22004GN | B12: =_xlfn.XLOOKUP(A12,'Product List'!B:B,'Product List'!I:I) -> Ceramic Candy Bowl | C12: 0 | D12: =SUMIFS(Purchase!F:F,Purchase!C:C,A12,Purchase!I:I,">"&$C$1,Purchase!V:V,"<>暂缓发货") -> 1248 | E12: =SUMIFS(Purchase!F:F,Purchase!C:C,A12,Purchase!J:J,">0",Purchase!I:I,">"&$C$1) -> 1248 | F12: =SUMIFS(Sales!E:E,Sales!C:C,A12,Sales!K:K,">"&$C$1) -> 672 | G12: =SUMIFS(Sales!E:E,Sales!C:C,A12,Sales!K:K,">"&$C$1,Sales!L:L,">0") -> 672 | H12: =C12+E12-G12-SUMIFS(Transfer!V:V,Transfer!O:O,A12)+SUMIFS(Transfer!W:W,Transfer!O:O,A12) -> 576 | I12: =D12-E12+SUMIFS(Transfer!V:V,Transfer!O:O,A12)-SUMIFS(Transfer!W:W,Transfer!O:O,A12) -> 0 | J12: =SUMIFS(Purchase!F:F,Purchase!C:C,A12,Purchase!V:V,"暂缓发货") -> 0 | K12: =F12-G12 -> 0 | L12: =H12-K12 -> 576 | M12: =H12+I12-K12 -> 576 | N12: =_xlfn.XLOOKUP(A12,'Product List'!B:B,'Product List'!F:F) -> C | O12: =SUMIF('Weekly Sales'!B:B,A12,'Weekly Sales'!R:R) -> 2.1666667 | P12: =IF(O12=0,999,ROUNDDOWN((L12)/O12,0)) -> 265 | Q12: =IF(O12=0,999,ROUNDDOWN((M12)/O12,0)) -> 265 | R12: =_xlfn.XLOOKUP(A12,'Product List'!B:B,'Product List'!P:P) -> 15 | S12: =IF(N12="A",6,IF(N12="B",5,2)) -> 2 | T12: =SUMIF('Weekly Sales'!B:B,A12,'Weekly Sales'!T:T) -> 0 | U12: =_xlfn.XLOOKUP(A12,'Product List'!B:B,'Product List'!O:O) -> 2000 | V12: =ROUNDUP(MAX(0,O12*(R12+S12+2)+T12-M12)/Y12,0)*Y12 -> 0 | W12: =_xlfn.XLOOKUP(A12,Sum_LA!A:A,Sum_LA!V:V) -> 0 | X12: =_xlfn.XLOOKUP(A12,Sum_HOU!A:A,Sum_HOU!V:V) -> 48 | Y12: {=_xlfn.XLOOKUP(1,('Case Pack'!A:A=A12)*('Case Pack'!F:F<=TODAY()),'Case Pack'!D:D,"未找到箱规")} -> 48 | Z12: =_xlfn.XLOOKUP(A12,'Product List'!B:B,'Product List'!M:M) -> PetcoMX,PSP | AA12: {=_xlfn.XLOOKUP(1,('Case Pack'!A:A=A12)*('Case Pack'!F:F<=TODAY()),'Case Pack'!G:G,"未找到箱规")} -> B | AB12: =V12/Y12 -> 0 | AC12: =_xlfn.XLOOKUP(AA12,'Case Type'!A:A,'Case Type'!H:H)*AB12 -> 0
A13: CPWJ0011 | B13: =_xlfn.XLOOKUP(A13,'Product List'!B:B,'Product List'!I:I) -> MINI/MOE MUSHROOM CABIN | C13: 0 | D13: =SUMIFS(Purchase!F:F,Purchase!C:C,A13,Purchase!I:I,">"&$C$1,Purchase!V:V,"<>暂缓发货") -> 2368 | E13: =SUMIFS(Purchase!F:F,Purchase!C:C,A13,Purchase!J:J,">0",Purchase!I:I,">"&$C$1) -> 1856 | F13: =SUMIFS(Sales!E:E,Sales!C:C,A13,Sales!K:K,">"&$C$1) -> 1360 | G13: =SUMIFS(Sales!E:E,Sales!C:C,A13,Sales!K:K,">"&$C$1,Sales!L:L,">0") -> 1296 | H13: =C13+E13-G13-SUMIFS(Transfer!V:V,Transfer!O:O,A13)+SUMIFS(Transfer!W:W,Transfer!O:O,A13) -> 560 | I13: =D13-E13+SUMIFS(Transfer!V:V,Transfer!O:O,A13)-SUMIFS(Transfer!W:W,Transfer!O:O,A13) -> 512 | J13: =SUMIFS(Purchase!F:F,Purchase!C:C,A13,Purchase!V:V,"暂缓发货") -> 0 | K13: =F13-G13 -> 64 | L13: =H13-K13 -> 496 | M13: =H13+I13-K13 -> 1008 | N13: =_xlfn.XLOOKUP(A13,'Product List'!B:B,'Product List'!F:F) -> B | O13: =SUMIF('Weekly Sales'!B:B,A13,'Weekly Sales'!R:R) -> 28.333333 | P13: =IF(O13=0,999,ROUNDDOWN((L13)/O13,0)) -> 17 | Q13: =IF(O13=0,999,ROUNDDOWN((M13)/O13,0)) -> 35 | R13: =_xlfn.XLOOKUP(A13,'Product List'!B:B,'Product List'!P:P) -> 15 | S13: =IF(N13="A",6,IF(N13="B",5,2)) -> 5 | T13: =SUMIF('Weekly Sales'!B:B,A13,'Weekly Sales'!T:T) -> 148.75 | U13: =_xlfn.XLOOKUP(A13,'Product List'!B:B,'Product List'!O:O) -> 500 | V13: =ROUNDUP(MAX(0,O13*(R13+S13+2)+T13-M13)/Y13,0)*Y13 -> 0 | W13: =_xlfn.XLOOKUP(A13,Sum_LA!A:A,Sum_LA!V:V) -> 0 | X13: =_xlfn.XLOOKUP(A13,Sum_HOU!A:A,Sum_HOU!V:V) -> 784 | Y13: {=_xlfn.XLOOKUP(1,('Case Pack'!A:A=A13)*('Case Pack'!F:F<=TODAY()),'Case Pack'!D:D,"未找到箱规")} -> 16 | Z13: =_xlfn.XLOOKUP(A13,'Product List'!B:B,'Product List'!M:M) -> PSP | AA13: {=_xlfn.XLOOKUP(1,('Case Pack'!A:A=A13)*('Case Pack'!F:F<=TODAY()),'Case Pack'!G:G,"未找到箱规")} -> C | AB13: =V13/Y13 -> 0 | AC13: =_xlfn.XLOOKUP(AA13,'Case Type'!A:A,'Case Type'!H:H)*AB13 -> 0
... A35: R-72 | B35: =_xlfn.XLOOKUP(A35,'Product List'!B:B,'Product List'!I:I) -> MMO-WAVE BRIDGE | C35: 352 | D35: =SUMIFS(Purchase!F:F,Purchase!C:C,A35,Purchase!I:I,">"&$C$1,Purchase!V:V,"<>暂缓发货") -> 2508 | E35: =SUMIFS(Purchase!F:F,Purchase!C:C,A35,Purchase!J:J,">0",Purchase!I:I,">"&$C$1) -> 2508 | F35: =SUMIFS(Sales!E:E,Sales!C:C,A35,Sales!K:K,">"&$C$1) -> 2853 | G35: =SUMIFS(Sales!E:E,Sales!C:C,A35,Sales!K:K,">"&$C$1,Sales!L:L,">0") -> 2853 | H35: =C35+E35-G35-SUMIFS(Transfer!V:V,Transfer!O:O,A35)+SUMIFS(Transfer!W:W,Transfer!O:O,A35) -> 7 | I35: =D35-E35+SUMIFS(Transfer!V:V,Transfer!O:O,A35)-SUMIFS(Transfer!W:W,Transfer!O:O,A35) -> 0 | J35: =SUMIFS(Purchase!F:F,Purchase!C:C,A35,Purchase!V:V,"暂缓发货") -> 0 | K35: =F35-G35 -> 0 | L35: =H35-K35 -> 7 | M35: =H35+I35-K35 -> 7 | N35: =_xlfn.XLOOKUP(A35,'Product List'!B:B,'Product List'!F:F) -> B | O35: =SUMIF('Weekly Sales'!B:B,A35,'Weekly Sales'!R:R) -> 0 | P35: =IF(O35=0,999,ROUNDDOWN((L35)/O35,0)) -> 999 | Q35: =IF(O35=0,999,ROUNDDOWN((M35)/O35,0)) -> 999 | R35: =_xlfn.XLOOKUP(A35,'Product List'!B:B,'Product List'!P:P) -> 15 | S35: =IF(N35="A",6,IF(N35="B",5,2)) -> 5 | T35: =SUMIF('Weekly Sales'!B:B,A35,'Weekly Sales'!T:T) -> 0 | U35: =_xlfn.XLOOKUP(A35,'Product List'!B:B,'Product List'!O:O) -> 500 | V35: =ROUNDUP(MAX(0,O35*(R35+S35+2)+T35-M35)/Y35,0)*Y35 -> 0 | W35: =_xlfn.XLOOKUP(A35,Sum_LA!A:A,Sum_LA!V:V) -> 0 | X35: =_xlfn.XLOOKUP(A35,Sum_HOU!A:A,Sum_HOU!V:V) -> 0 | Y35: {=_xlfn.XLOOKUP(1,('Case Pack'!A:A=A35)*('Case Pack'!F:F<=TODAY()),'Case Pack'!D:D,"未找到箱规")} -> 33 | Z35: =_xlfn.XLOOKUP(A35,'Product List'!B:B,'Product List'!M:M) -> PetcoUS，Canada | AA35: {=_xlfn.XLOOKUP(1,('Case Pack'!A:A=A35)*('Case Pack'!F:F<=TODAY()),'Case Pack'!G:G,"未找到箱规")} -> C | AB35: =V35/Y35 -> 0 | AC35: =_xlfn.XLOOKUP(AA35,'Case Type'!A:A,'Case Type'!H:H)*AB35 -> 0
A36: R-8 | B36: =_xlfn.XLOOKUP(A36,'Product List'!B:B,'Product List'!I:I) -> MINI/MOE BENDABLE BIRCHWOOD FENCE | C36: =746 -> 746 | D36: =SUMIFS(Purchase!F:F,Purchase!C:C,A36,Purchase!I:I,">"&$C$1,Purchase!V:V,"<>暂缓发货") -> 2592 | E36: =SUMIFS(Purchase!F:F,Purchase!C:C,A36,Purchase!J:J,">0",Purchase!I:I,">"&$C$1) -> 2592 | F36: =SUMIFS(Sales!E:E,Sales!C:C,A36,Sales!K:K,">"&$C$1) -> 2634 | G36: =SUMIFS(Sales!E:E,Sales!C:C,A36,Sales!K:K,">"&$C$1,Sales!L:L,">0") -> 2634 | H36: =C36+E36-G36-SUMIFS(Transfer!V:V,Transfer!O:O,A36)+SUMIFS(Transfer!W:W,Transfer!O:O,A36) -> 704 | I36: =D36-E36+SUMIFS(Transfer!V:V,Transfer!O:O,A36)-SUMIFS(Transfer!W:W,Transfer!O:O,A36) -> 0 | J36: =SUMIFS(Purchase!F:F,Purchase!C:C,A36,Purchase!V:V,"暂缓发货") -> 0 | K36: =F36-G36 -> 0 | L36: =H36-K36 -> 704 | M36: =H36+I36-K36 -> 704 | N36: =_xlfn.XLOOKUP(A36,'Product List'!B:B,'Product List'!F:F) -> B | O36: =SUMIF('Weekly Sales'!B:B,A36,'Weekly Sales'!R:R) -> 16 | P36: =IF(O36=0,999,ROUNDDOWN((L36)/O36,0)) -> 44 | Q36: =IF(O36=0,999,ROUNDDOWN((M36)/O36,0)) -> 44 | R36: =_xlfn.XLOOKUP(A36,'Product List'!B:B,'Product List'!P:P) -> 15 | S36: =IF(N36="A",6,IF(N36="B",5,2)) -> 5 | T36: =SUMIF('Weekly Sales'!B:B,A36,'Weekly Sales'!T:T) -> 84 | U36: =_xlfn.XLOOKUP(A36,'Product List'!B:B,'Product List'!O:O) -> 500 | V36: =ROUNDUP(MAX(0,O36*(R36+S36+2)+T36-M36)/Y36,0)*Y36 -> 0 | W36: =_xlfn.XLOOKUP(A36,Sum_LA!A:A,Sum_LA!V:V) -> 0 | X36: =_xlfn.XLOOKUP(A36,Sum_HOU!A:A,Sum_HOU!V:V) -> 448 | Y36: {=_xlfn.XLOOKUP(1,('Case Pack'!A:A=A36)*('Case Pack'!F:F<=TODAY()),'Case Pack'!D:D,"未找到箱规")} -> 32 | Z36: =_xlfn.XLOOKUP(A36,'Product List'!B:B,'Product List'!M:M) -> PSP, PetcoUS | AA36: {=_xlfn.XLOOKUP(1,('Case Pack'!A:A=A36)*('Case Pack'!F:F<=TODAY()),'Case Pack'!G:G,"未找到箱规")} -> F | AB36: =V36/Y36 -> 0 | AC36: =_xlfn.XLOOKUP(AA36,'Case Type'!A:A,'Case Type'!H:H)*AB36 -> 0
A37: RJ510-BL | B37: =_xlfn.XLOOKUP(A37,'Product List'!B:B,'Product List'!I:I) -> Crystal Outdoor Cage | C37: 0 | D37: =SUMIFS(Purchase!F:F,Purchase!C:C,A37,Purchase!I:I,">"&$C$1,Purchase!V:V,"<>暂缓发货") -> 1250 | E37: =SUMIFS(Purchase!F:F,Purchase!C:C,A37,Purchase!J:J,">0",Purchase!I:I,">"&$C$1) -> 1250 | F37: =SUMIFS(Sales!E:E,Sales!C:C,A37,Sales!K:K,">"&$C$1) -> 305 | G37: =SUMIFS(Sales!E:E,Sales!C:C,A37,Sales!K:K,">"&$C$1,Sales!L:L,">0") -> 305 | H37: =C37+E37-G37-SUMIFS(Transfer!V:V,Transfer!O:O,A37)+SUMIFS(Transfer!W:W,Transfer!O:O,A37) -> 945 | I37: =D37-E37+SUMIFS(Transfer!V:V,Transfer!O:O,A37)-SUMIFS(Transfer!W:W,Transfer!O:O,A37) -> 0 | J37: =SUMIFS(Purchase!F:F,Purchase!C:C,A37,Purchase!V:V,"暂缓发货") -> 0 | K37: =F37-G37 -> 0 | L37: =H37-K37 -> 945 | M37: =H37+I37-K37 -> 945 | N37: =_xlfn.XLOOKUP(A37,'Product List'!B:B,'Product List'!F:F) -> C | O37: =SUMIF('Weekly Sales'!B:B,A37,'Weekly Sales'!R:R) -> 0.66666667 | P37: =IF(O37=0,999,ROUNDDOWN((L37)/O37,0)) -> 1417 | Q37: =IF(O37=0,999,ROUNDDOWN((M37)/O37,0)) -> 1417 | R37: =_xlfn.XLOOKUP(A37,'Product List'!B:B,'Product List'!P:P) -> 10 | S37: =IF(N37="A",6,IF(N37="B",5,2)) -> 2 | T37: =SUMIF('Weekly Sales'!B:B,A37,'Weekly Sales'!T:T) -> 0 | U37: =_xlfn.XLOOKUP(A37,'Product List'!B:B,'Product List'!O:O) -> 1000 | V37: =ROUNDUP(MAX(0,O37*(R37+S37+2)+T37-M37)/Y37,0)*Y37 -> 0 | W37: =_xlfn.XLOOKUP(A37,Sum_LA!A:A,Sum_LA!V:V) -> 0 | X37: =_xlfn.XLOOKUP(A37,Sum_HOU!A:A,Sum_HOU!V:V) -> 10 | Y37: {=_xlfn.XLOOKUP(1,('Case Pack'!A:A=A37)*('Case Pack'!F:F<=TODAY()),'Case Pack'!D:D,"未找到箱规")} -> 5 | Z37: =_xlfn.XLOOKUP(A37,'Product List'!B:B,'Product List'!M:M) -> PetcoMX,PSP，Canada | AA37: {=_xlfn.XLOOKUP(1,('Case Pack'!A:A=A37)*('Case Pack'!F:F<=TODAY()),'Case Pack'!G:G,"未找到箱规")} -> A | AB37: =V37/Y37 -> 0 | AC37: =_xlfn.XLOOKUP(AA37,'Case Type'!A:A,'Case Type'!H:H)*AB37 -> 0
A38: SP-4 | B38: =_xlfn.XLOOKUP(A38,'Product List'!B:B,'Product List'!I:I) -> D. MMO-COTTAGE VIEW CAGE | C38: 0 | D38: =SUMIFS(Purchase!F:F,Purchase!C:C,A38,Purchase!I:I,">"&$C$1,Purchase!V:V,"<>暂缓发货") -> 741 | E38: =SUMIFS(Purchase!F:F,Purchase!C:C,A38,Purchase!J:J,">0",Purchase!I:I,">"&$C$1) -> 741 | F38: =SUMIFS(Sales!E:E,Sales!C:C,A38,Sales!K:K,">"&$C$1) -> 306 | G38: =SUMIFS(Sales!E:E,Sales!C:C,A38,Sales!K:K,">"&$C$1,Sales!L:L,">0") -> 137 | H38: =C38+E38-G38-SUMIFS(Transfer!V:V,Transfer!O:O,A38)+SUMIFS(Transfer!W:W,Transfer!O:O,A38) -> 604 | I38: =D38-E38+SUMIFS(Transfer!V:V,Transfer!O:O,A38)-SUMIFS(Transfer!W:W,Transfer!O:O,A38) -> 0 | J38: =SUMIFS(Purchase!F:F,Purchase!C:C,A38,Purchase!V:V,"暂缓发货") -> 0 | K38: =F38-G38 -> 169 | L38: =H38-K38 -> 435 | M38: =H38+I38-K38 -> 435 | N38: =_xlfn.XLOOKUP(A38,'Product List'!B:B,'Product List'!F:F) -> A | O38: =SUMIF('Weekly Sales'!B:B,A38,'Weekly Sales'!R:R) -> 0 | P38: =IF(O38=0,999,ROUNDDOWN((L38)/O38,0)) -> 999 | Q38: =IF(O38=0,999,ROUNDDOWN((M38)/O38,0)) -> 999 | R38: =_xlfn.XLOOKUP(A38,'Product List'!B:B,'Product List'!P:P) -> 10 | S38: =IF(N38="A",6,IF(N38="B",5,2)) -> 6 | T38: =SUMIF('Weekly Sales'!B:B,A38,'Weekly Sales'!T:T) -> 0 | U38: =_xlfn.XLOOKUP(A38,'Product List'!B:B,'Product List'!O:O) -> 1000 | V38: =ROUNDUP(MAX(0,O38*(R38+S38+2)+T38-M38)/Y38,0)*Y38 -> 0 | W38: =_xlfn.XLOOKUP(A38,Sum_LA!A:A,Sum_LA!V:V) -> 0 | X38: =_xlfn.XLOOKUP(A38,Sum_HOU!A:A,Sum_HOU!V:V) -> 0 | Y38: {=_xlfn.XLOOKUP(1,('Case Pack'!A:A=A38)*('Case Pack'!F:F<=TODAY()),'Case Pack'!D:D,"未找到箱规")} -> 1 | Z38: =_xlfn.XLOOKUP(A38,'Product List'!B:B,'Product List'!M:M) -> PSP, PetcoUS, PetcoMX | AA38: {=_xlfn.XLOOKUP(1,('Case Pack'!A:A=A38)*('Case Pack'!F:F<=TODAY()),'Case Pack'!G:G,"未找到箱规")} -> S3 | AB38: =V38/Y38 -> 0 | AC38: =_xlfn.XLOOKUP(AA38,'Case Type'!A:A,'Case Type'!H:H)*AB38 -> 0
A39: SP-7 | B39: =_xlfn.XLOOKUP(A39,'Product List'!B:B,'Product List'!I:I) -> MINI/MOE ROCKING BIRDHOUSE HIDE 1EA | C39: 0 | D39: =SUMIFS(Purchase!F:F,Purchase!C:C,A39,Purchase!I:I,">"&$C$1,Purchase!V:V,"<>暂缓发货") -> 0 | E39: =SUMIFS(Purchase!F:F,Purchase!C:C,A39,Purchase!J:J,">0",Purchase!I:I,">"&$C$1) -> 0 | F39: =SUMIFS(Sales!E:E,Sales!C:C,A39,Sales!K:K,">"&$C$1) -> 0 | G39: =SUMIFS(Sales!E:E,Sales!C:C,A39,Sales!K:K,">"&$C$1,Sales!L:L,">0") -> 0 | H39: =C39+E39-G39-SUMIFS(Transfer!V:V,Transfer!O:O,A39)+SUMIFS(Transfer!W:W,Transfer!O:O,A39) -> 0 | I39: =D39-E39+SUMIFS(Transfer!V:V,Transfer!O:O,A39)-SUMIFS(Transfer!W:W,Transfer!O:O,A39) -> 0 | J39: =SUMIFS(Purchase!F:F,Purchase!C:C,A39,Purchase!V:V,"暂缓发货") -> 0 | K39: =F39-G39 -> 0 | L39: =H39-K39 -> 0 | M39: =H39+I39-K39 -> 0 | N39: =_xlfn.XLOOKUP(A39,'Product List'!B:B,'Product List'!F:F) -> C | O39: =SUMIF('Weekly Sales'!B:B,A39,'Weekly Sales'!R:R) -> 0 | P39: =IF(O39=0,999,ROUNDDOWN((L39)/O39,0)) -> 999 | Q39: =IF(O39=0,999,ROUNDDOWN((M39)/O39,0)) -> 999 | R39: =_xlfn.XLOOKUP(A39,'Product List'!B:B,'Product List'!P:P) -> 10 | S39: =IF(N39="A",6,IF(N39="B",5,2)) -> 2 | T39: =SUMIF('Weekly Sales'!B:B,A39,'Weekly Sales'!T:T) -> 0 | U39: =_xlfn.XLOOKUP(A39,'Product List'!B:B,'Product List'!O:O) -> 500 | V39: =ROUNDUP(MAX(0,O39*(R39+S39+2)+T39-M39)/Y39,0)*Y39 -> 0 | W39: =_xlfn.XLOOKUP(A39,Sum_LA!A:A,Sum_LA!V:V) -> 0 | X39: =_xlfn.XLOOKUP(A39,Sum_HOU!A:A,Sum_HOU!V:V) -> 0 | Y39: {=_xlfn.XLOOKUP(1,('Case Pack'!A:A=A39)*('Case Pack'!F:F<=TODAY()),'Case Pack'!D:D,"未找到箱规")} -> 18 | Z39: =_xlfn.XLOOKUP(A39,'Product List'!B:B,'Product List'!M:M) -> PSP | AA39: {=_xlfn.XLOOKUP(1,('Case Pack'!A:A=A39)*('Case Pack'!F:F<=TODAY()),'Case Pack'!G:G,"未找到箱规")} -> C | AB39: =V39/Y39 -> 0 | AC39: =_xlfn.XLOOKUP(AA39,'Case Type'!A:A,'Case Type'!H:H)*AB39 -> 0
A40: SZP542-GN | B40: =_xlfn.XLOOKUP(A40,'Product List'!B:B,'Product List'!I:I) -> Bubble water bottle (color:green) | C40: 144 | D40: =SUMIFS(Purchase!F:F,Purchase!C:C,A40,Purchase!I:I,">"&$C$1,Purchase!V:V,"<>暂缓发货") -> 288 | E40: =SUMIFS(Purchase!F:F,Purchase!C:C,A40,Purchase!J:J,">0",Purchase!I:I,">"&$C$1) -> 288 | F40: =SUMIFS(Sales!E:E,Sales!C:C,A40,Sales!K:K,">"&$C$1) -> 198 | G40: =SUMIFS(Sales!E:E,Sales!C:C,A40,Sales!K:K,">"&$C$1,Sales!L:L,">0") -> 198 | H40: =C40+E40-G40-SUMIFS(Transfer!V:V,Transfer!O:O,A40)+SUMIFS(Transfer!W:W,Transfer!O:O,A40) -> 234 | I40: =D40-E40+SUMIFS(Transfer!V:V,Transfer!O:O,A40)-SUMIFS(Transfer!W:W,Transfer!O:O,A40) -> 0 | J40: =SUMIFS(Purchase!F:F,Purchase!C:C,A40,Purchase!V:V,"暂缓发货") -> 0 | K40: =F40-G40 -> 0 | L40: =H40-K40 -> 234 | M40: =H40+I40-K40 -> 234 | N40: =_xlfn.XLOOKUP(A40,'Product List'!B:B,'Product List'!F:F) -> C | O40: =SUMIF('Weekly Sales'!B:B,A40,'Weekly Sales'!R:R) -> 0 | P40: =IF(O40=0,999,ROUNDDOWN((L40)/O40,0)) -> 999 | Q40: =IF(O40=0,999,ROUNDDOWN((M40)/O40,0)) -> 999 | R40: =_xlfn.XLOOKUP(A40,'Product List'!B:B,'Product List'!P:P) -> 10 | S40: =IF(N40="A",6,IF(N40="B",5,2)) -> 2 | T40: =SUMIF('Weekly Sales'!B:B,A40,'Weekly Sales'!T:T) -> 0 | U40: =_xlfn.XLOOKUP(A40,'Product List'!B:B,'Product List'!O:O) -> 1000 | V40: =ROUNDUP(MAX(0,O40*(R40+S40+2)+T40-M40)/Y40,0)*Y40 -> 0 | W40: =_xlfn.XLOOKUP(A40,Sum_LA!A:A,Sum_LA!V:V) -> 0 | X40: =_xlfn.XLOOKUP(A40,Sum_HOU!A:A,Sum_HOU!V:V) -> 0 | Y40: {=_xlfn.XLOOKUP(1,('Case Pack'!A:A=A40)*('Case Pack'!F:F<=TODAY()),'Case Pack'!D:D,"未找到箱规")} -> 18 | Z40: =_xlfn.XLOOKUP(A40,'Product List'!B:B,'Product List'!M:M) -> Pet Supermarket,PetcoMX | AA40: {=_xlfn.XLOOKUP(1,('Case Pack'!A:A=A40)*('Case Pack'!F:F<=TODAY()),'Case Pack'!G:G,"未找到箱规")} -> B | AB40: =V40/Y40 -> 0 | AC40: =_xlfn.XLOOKUP(AA40,'Case Type'!A:A,'Case Type'!H:H)*AB40 -> 0
A41: SZP542-WH | B41: =_xlfn.XLOOKUP(A41,'Product List'!B:B,'Product List'!I:I) -> MMO-BUBBLE WATER BOTTLE | C41: 360 | D41: =SUMIFS(Purchase!F:F,Purchase!C:C,A41,Purchase!I:I,">"&$C$1,Purchase!V:V,"<>暂缓发货") -> 18648 | E41: =SUMIFS(Purchase!F:F,Purchase!C:C,A41,Purchase!J:J,">0",Purchase!I:I,">"&$C$1) -> 18648 | F41: =SUMIFS(Sales!E:E,Sales!C:C,A41,Sales!K:K,">"&$C$1) -> 13590 | G41: =SUMIFS(Sales!E:E,Sales!C:C,A41,Sales!K:K,">"&$C$1,Sales!L:L,">0") -> 10566 | H41: =C41+E41-G41-SUMIFS(Transfer!V:V,Transfer!O:O,A41)+SUMIFS(Transfer!W:W,Transfer!O:O,A41) -> 8442 | I41: =D41-E41+SUMIFS(Transfer!V:V,Transfer!O:O,A41)-SUMIFS(Transfer!W:W,Transfer!O:O,A41) -> 0 | J41: =SUMIFS(Purchase!F:F,Purchase!C:C,A41,Purchase!V:V,"暂缓发货") -> 5124 | K41: =F41-G41 -> 3024 | L41: =H41-K41 -> 5418 | M41: =H41+I41-K41 -> 5418 | N41: =_xlfn.XLOOKUP(A41,'Product List'!B:B,'Product List'!F:F) -> A | O41: =SUMIF('Weekly Sales'!B:B,A41,'Weekly Sales'!R:R) -> 321.16667 | P41: =IF(O41=0,999,ROUNDDOWN((L41)/O41,0)) -> 16 | Q41: =IF(O41=0,999,ROUNDDOWN((M41)/O41,0)) -> 16 | R41: =_xlfn.XLOOKUP(A41,'Product List'!B:B,'Product List'!P:P) -> 10 | S41: =IF(N41="A",6,IF(N41="B",5,2)) -> 6 | T41: =SUMIF('Weekly Sales'!B:B,A41,'Weekly Sales'!T:T) -> 2101.5833 | U41: =_xlfn.XLOOKUP(A41,'Product List'!B:B,'Product List'!O:O) -> 1000 | V41: =ROUNDUP(MAX(0,O41*(R41+S41+2)+T41-M41)/Y41,0)*Y41 -> 2478 | W41: =_xlfn.XLOOKUP(A41,Sum_LA!A:A,Sum_LA!V:V) -> 2394 | X41: =_xlfn.XLOOKUP(A41,Sum_HOU!A:A,Sum_HOU!V:V) -> 126 | Y41: {=_xlfn.XLOOKUP(1,('Case Pack'!A:A=A41)*('Case Pack'!F:F<=TODAY()),'Case Pack'!D:D,"未找到箱规")} -> 42 | Z41: =_xlfn.XLOOKUP(A41,'Product List'!B:B,'Product List'!M:M) -> PetcoUS,PSP | AA41: {=_xlfn.XLOOKUP(1,('Case Pack'!A:A=A41)*('Case Pack'!F:F<=TODAY()),'Case Pack'!G:G,"未找到箱规")} -> C | AB41: =V41/Y41 -> 59 | AC41: =_xlfn.XLOOKUP(AA41,'Case Type'!A:A,'Case Type'!H:H)*AB41 -> 9.281633
A42: T-1-BL | B42: =_xlfn.XLOOKUP(A42,'Product List'!B:B,'Product List'!I:I) -> MMO-PAPER TWIST BLU/WHT | C42: 936 | D42: =SUMIFS(Purchase!F:F,Purchase!C:C,A42,Purchase!I:I,">"&$C$1,Purchase!V:V,"<>暂缓发货") -> 4740 | E42: =SUMIFS(Purchase!F:F,Purchase!C:C,A42,Purchase!J:J,">0",Purchase!I:I,">"&$C$1) -> 4740 | F42: =SUMIFS(Sales!E:E,Sales!C:C,A42,Sales!K:K,">"&$C$1) -> 2136 | G42: =SUMIFS(Sales!E:E,Sales!C:C,A42,Sales!K:K,">"&$C$1,Sales!L:L,">0") -> 2136 | H42: =C42+E42-G42-SUMIFS(Transfer!V:V,Transfer!O:O,A42)+SUMIFS(Transfer!W:W,Transfer!O:O,A42) -> 3540 | I42: =D42-E42+SUMIFS(Transfer!V:V,Transfer!O:O,A42)-SUMIFS(Transfer!W:W,Transfer!O:O,A42) -> 0 | J42: =SUMIFS(Purchase!F:F,Purchase!C:C,A42,Purchase!V:V,"暂缓发货") -> 0 | K42: =F42-G42 -> 0 | L42: =H42-K42 -> 3540 | M42: =H42+I42-K42 -> 3540 | N42: =_xlfn.XLOOKUP(A42,'Product List'!B:B,'Product List'!F:F) -> B | O42: =SUMIF('Weekly Sales'!B:B,A42,'Weekly Sales'!R:R) -> 48.5 | P42: =IF(O42=0,999,ROUNDDOWN((L42)/O42,0)) -> 72 | Q42: =IF(O42=0,999,ROUNDDOWN((M42)/O42,0)) -> 72 | R42: =_xlfn.XLOOKUP(A42,'Product List'!B:B,'Product List'!P:P) -> 10 | S42: =IF(N42="A",6,IF(N42="B",5,2)) -> 5 | T42: =SUMIF('Weekly Sales'!B:B,A42,'Weekly Sales'!T:T) -> 157.625 | U42: =_xlfn.XLOOKUP(A42,'Product List'!B:B,'Product List'!O:O) -> 500 | V42: =ROUNDUP(MAX(0,O42*(R42+S42+2)+T42-M42)/Y42,0)*Y42 -> 0 | W42: =_xlfn.XLOOKUP(A42,Sum_LA!A:A,Sum_LA!V:V) -> 0 | X42: =_xlfn.XLOOKUP(A42,Sum_HOU!A:A,Sum_HOU!V:V) -> 0 | Y42: {=_xlfn.XLOOKUP(1,('Case Pack'!A:A=A42)*('Case Pack'!F:F<=TODAY()),'Case Pack'!D:D,"未找到箱规")} -> 30 | Z42: =_xlfn.XLOOKUP(A42,'Product List'!B:B,'Product List'!M:M) -> PetcoUS，PSP | AA42: {=_xlfn.XLOOKUP(1,('Case Pack'!A:A=A42)*('Case Pack'!F:F<=TODAY()),'Case Pack'!G:G,"未找到箱规")} -> A | AB42: =V42/Y42 -> 0 | AC42: =_xlfn.XLOOKUP(AA42,'Case Type'!A:A,'Case Type'!H:H)*AB42 -> 0
A43: T-1-BL-WH | B43: =_xlfn.XLOOKUP(A43,'Product List'!B:B,'Product List'!I:I) -> MINI/MOE SMALL ANIMAL BEDDING PAPER TWISTS | C43: 0 | D43: =SUMIFS(Purchase!F:F,Purchase!C:C,A43,Purchase!I:I,">"&$C$1,Purchase!V:V,"<>暂缓发货") -> 3420 | E43: =SUMIFS(Purchase!F:F,Purchase!C:C,A43,Purchase!J:J,">0",Purchase!I:I,">"&$C$1) -> 3390 | F43: =SUMIFS(Sales!E:E,Sales!C:C,A43,Sales!K:K,">"&$C$1) -> 2010 | G43: =SUMIFS(Sales!E:E,Sales!C:C,A43,Sales!K:K,">"&$C$1,Sales!L:L,">0") -> 2010 | H43: =C43+E43-G43-SUMIFS(Transfer!V:V,Transfer!O:O,A43)+SUMIFS(Transfer!W:W,Transfer!O:O,A43) -> 1380 | I43: =D43-E43+SUMIFS(Transfer!V:V,Transfer!O:O,A43)-SUMIFS(Transfer!W:W,Transfer!O:O,A43) -> 30 | J43: =SUMIFS(Purchase!F:F,Purchase!C:C,A43,Purchase!V:V,"暂缓发货") -> 0 | K43: =F43-G43 -> 0 | L43: =H43-K43 -> 1380 | M43: =H43+I43-K43 -> 1410 | N43: =_xlfn.XLOOKUP(A43,'Product List'!B:B,'Product List'!F:F) -> C | O43: =SUMIF('Weekly Sales'!B:B,A43,'Weekly Sales'!R:R) -> 9.1666667 | P43: =IF(O43=0,999,ROUNDDOWN((L43)/O43,0)) -> 150 | Q43: =IF(O43=0,999,ROUNDDOWN((M43)/O43,0)) -> 153 | R43: =_xlfn.XLOOKUP(A43,'Product List'!B:B,'Product List'!P:P) -> 10 | S43: =IF(N43="A",6,IF(N43="B",5,2)) -> 2 | T43: =SUMIF('Weekly Sales'!B:B,A43,'Weekly Sales'!T:T) -> 0 | U43: =_xlfn.XLOOKUP(A43,'Product List'!B:B,'Product List'!O:O) -> 1000 | V43: =ROUNDUP(MAX(0,O43*(R43+S43+2)+T43-M43)/Y43,0)*Y43 -> 0 | W43: =_xlfn.XLOOKUP(A43,Sum_LA!A:A,Sum_LA!V:V) -> 0 | X43: =_xlfn.XLOOKUP(A43,Sum_HOU!A:A,Sum_HOU!V:V) -> 150 | Y43: {=_xlfn.XLOOKUP(1,('Case Pack'!A:A=A43)*('Case Pack'!F:F<=TODAY()),'Case Pack'!D:D,"未找到箱规")} -> 30 | Z43: =_xlfn.XLOOKUP(A43,'Product List'!B:B,'Product List'!M:M) -> PSP | AA43: {=_xlfn.XLOOKUP(1,('Case Pack'!A:A=A43)*('Case Pack'!F:F<=TODAY()),'Case Pack'!G:G,"未找到箱规")} -> A | AB43: =V43/Y43 -> 0 | AC43: =_xlfn.XLOOKUP(AA43,'Case Type'!A:A,'Case Type'!H:H)*AB43 -> 0
A44: T-1-BR-WH | B44: =_xlfn.XLOOKUP(A44,'Product List'!B:B,'Product List'!I:I) -> Paper twist brown / white bedding | C44: 0 | D44: =SUMIFS(Purchase!F:F,Purchase!C:C,A44,Purchase!I:I,">"&$C$1,Purchase!V:V,"<>暂缓发货") -> 1860 | E44: =SUMIFS(Purchase!F:F,Purchase!C:C,A44,Purchase!J:J,">0",Purchase!I:I,">"&$C$1) -> 1860 | F44: =SUMIFS(Sales!E:E,Sales!C:C,A44,Sales!K:K,">"&$C$1) -> 930 | G44: =SUMIFS(Sales!E:E,Sales!C:C,A44,Sales!K:K,">"&$C$1,Sales!L:L,">0") -> 930 | H44: =C44+E44-G44-SUMIFS(Transfer!V:V,Transfer!O:O,A44)+SUMIFS(Transfer!W:W,Transfer!O:O,A44) -> 930 | I44: =D44-E44+SUMIFS(Transfer!V:V,Transfer!O:O,A44)-SUMIFS(Transfer!W:W,Transfer!O:O,A44) -> 0 | J44: =SUMIFS(Purchase!F:F,Purchase!C:C,A44,Purchase!V:V,"暂缓发货") -> 0 | K44: =F44-G44 -> 0 | L44: =H44-K44 -> 930 | M44: =H44+I44-K44 -> 930 | N44: =_xlfn.XLOOKUP(A44,'Product List'!B:B,'Product List'!F:F) -> C | O44: =SUMIF('Weekly Sales'!B:B,A44,'Weekly Sales'!R:R) -> 0.5 | P44: =IF(O44=0,999,ROUNDDOWN((L44)/O44,0)) -> 1860 | Q44: =IF(O44=0,999,ROUNDDOWN((M44)/O44,0)) -> 1860 | R44: =_xlfn.XLOOKUP(A44,'Product List'!B:B,'Product List'!P:P) -> 10 | S44: =IF(N44="A",6,IF(N44="B",5,2)) -> 2 | T44: =SUMIF('Weekly Sales'!B:B,A44,'Weekly Sales'!T:T) -> 0 | U44: =_xlfn.XLOOKUP(A44,'Product List'!B:B,'Product List'!O:O) -> 1000 | V44: =ROUNDUP(MAX(0,O44*(R44+S44+2)+T44-M44)/Y44,0)*Y44 -> 0 | W44: =_xlfn.XLOOKUP(A44,Sum_LA!A:A,Sum_LA!V:V) -> 0 | X44: =_xlfn.XLOOKUP(A44,Sum_HOU!A:A,Sum_HOU!V:V) -> 30 | Y44: {=_xlfn.XLOOKUP(1,('Case Pack'!A:A=A44)*('Case Pack'!F:F<=TODAY()),'Case Pack'!D:D,"未找到箱规")} -> 30 | Z44: =_xlfn.XLOOKUP(A44,'Product List'!B:B,'Product List'!M:M) -> Pet Supermarket，PSP | AA44: {=_xlfn.XLOOKUP(1,('Case Pack'!A:A=A44)*('Case Pack'!F:F<=TODAY()),'Case Pack'!G:G,"未找到箱规")} -> A | AB44: =V44/Y44 -> 0 | AC44: =_xlfn.XLOOKUP(AA44,'Case Type'!A:A,'Case Type'!H:H)*AB44 -> 0
A45: T-1-PK | B45: =_xlfn.XLOOKUP(A45,'Product List'!B:B,'Product List'!I:I) -> MINI/MOE SMALL ANIMAL BEDDING PAPER TWISTS BUBBLEGUM 1EA | C45: 0 | D45: =SUMIFS(Purchase!F:F,Purchase!C:C,A45,Purchase!I:I,">"&$C$1,Purchase!V:V,"<>暂缓发货") -> 1260 | E45: =SUMIFS(Purchase!F:F,Purchase!C:C,A45,Purchase!J:J,">0",Purchase!I:I,">"&$C$1) -> 1260 | F45: =SUMIFS(Sales!E:E,Sales!C:C,A45,Sales!K:K,">"&$C$1) -> 660 | G45: =SUMIFS(Sales!E:E,Sales!C:C,A45,Sales!K:K,">"&$C$1,Sales!L:L,">0") -> 660 | H45: =C45+E45-G45-SUMIFS(Transfer!V:V,Transfer!O:O,A45)+SUMIFS(Transfer!W:W,Transfer!O:O,A45) -> 600 | I45: =D45-E45+SUMIFS(Transfer!V:V,Transfer!O:O,A45)-SUMIFS(Transfer!W:W,Transfer!O:O,A45) -> 0 | J45: =SUMIFS(Purchase!F:F,Purchase!C:C,A45,Purchase!V:V,"暂缓发货") -> 0 | K45: =F45-G45 -> 0 | L45: =H45-K45 -> 600 | M45: =H45+I45-K45 -> 600 | N45: =_xlfn.XLOOKUP(A45,'Product List'!B:B,'Product List'!F:F) -> C | O45: =SUMIF('Weekly Sales'!B:B,A45,'Weekly Sales'!R:R) -> 1.6666667 | P45: =IF(O45=0,999,ROUNDDOWN((L45)/O45,0)) -> 359 | Q45: =IF(O45=0,999,ROUNDDOWN((M45)/O45,0)) -> 359 | R45: =_xlfn.XLOOKUP(A45,'Product List'!B:B,'Product List'!P:P) -> 10 | S45: =IF(N45="A",6,IF(N45="B",5,2)) -> 2 | T45: =SUMIF('Weekly Sales'!B:B,A45,'Weekly Sales'!T:T) -> 0 | U45: =_xlfn.XLOOKUP(A45,'Product List'!B:B,'Product List'!O:O) -> 1000 | V45: =ROUNDUP(MAX(0,O45*(R45+S45+2)+T45-M45)/Y45,0)*Y45 -> 0 | W45: =_xlfn.XLOOKUP(A45,Sum_LA!A:A,Sum_LA!V:V) -> 0 | X45: =_xlfn.XLOOKUP(A45,Sum_HOU!A:A,Sum_HOU!V:V) -> 30 | Y45: {=_xlfn.XLOOKUP(1,('Case Pack'!A:A=A45)*('Case Pack'!F:F<=TODAY()),'Case Pack'!D:D,"未找到箱规")} -> 30 | Z45: =_xlfn.XLOOKUP(A45,'Product List'!B:B,'Product List'!M:M) -> PSP | AA45: {=_xlfn.XLOOKUP(1,('Case Pack'!A:A=A45)*('Case Pack'!F:F<=TODAY()),'Case Pack'!G:G,"未找到箱规")} -> A | AB45: =V45/Y45 -> 0 | AC45: =_xlfn.XLOOKUP(AA45,'Case Type'!A:A,'Case Type'!H:H)*AB45 -> 0
A46: T-41 | B46: =_xlfn.XLOOKUP(A46,'Product List'!B:B,'Product List'!I:I) -> Forest Series Hamster Chew Toy & Treat | C46: 0 | D46: =SUMIFS(Purchase!F:F,Purchase!C:C,A46,Purchase!I:I,">"&$C$1,Purchase!V:V,"<>暂缓发货") -> 1560 | E46: =SUMIFS(Purchase!F:F,Purchase!C:C,A46,Purchase!J:J,">0",Purchase!I:I,">"&$C$1) -> 1560 | F46: =SUMIFS(Sales!E:E,Sales!C:C,A46,Sales!K:K,">"&$C$1) -> 1020 | G46: =SUMIFS(Sales!E:E,Sales!C:C,A46,Sales!K:K,">"&$C$1,Sales!L:L,">0") -> 1020 | H46: =C46+E46-G46-SUMIFS(Transfer!V:V,Transfer!O:O,A46)+SUMIFS(Transfer!W:W,Transfer!O:O,A46) -> 540 | I46: =D46-E46+SUMIFS(Transfer!V:V,Transfer!O:O,A46)-SUMIFS(Transfer!W:W,Transfer!O:O,A46) -> 0 | J46: =SUMIFS(Purchase!F:F,Purchase!C:C,A46,Purchase!V:V,"暂缓发货") -> 0 | K46: =F46-G46 -> 0 | L46: =H46-K46 -> 540 | M46: =H46+I46-K46 -> 540 | N46: =_xlfn.XLOOKUP(A46,'Product List'!B:B,'Product List'!F:F) -> C | O46: =SUMIF('Weekly Sales'!B:B,A46,'Weekly Sales'!R:R) -> 3 | P46: =IF(O46=0,999,ROUNDDOWN((L46)/O46,0)) -> 180 | Q46: =IF(O46=0,999,ROUNDDOWN((M46)/O46,0)) -> 180 | R46: =_xlfn.XLOOKUP(A46,'Product List'!B:B,'Product List'!P:P) -> 10 | S46: =IF(N46="A",6,IF(N46="B",5,2)) -> 2 | T46: =SUMIF('Weekly Sales'!B:B,A46,'Weekly Sales'!T:T) -> 0 | U46: =_xlfn.XLOOKUP(A46,'Product List'!B:B,'Product List'!O:O) -> 1000 | V46: =ROUNDUP(MAX(0,O46*(R46+S46+2)+T46-M46)/Y46,0)*Y46 -> 0 | W46: =_xlfn.XLOOKUP(A46,Sum_LA!A:A,Sum_LA!V:V) -> 0 | X46: =_xlfn.XLOOKUP(A46,Sum_HOU!A:A,Sum_HOU!V:V) -> 60 | Y46: {=_xlfn.XLOOKUP(1,('Case Pack'!A:A=A46)*('Case Pack'!F:F<=TODAY()),'Case Pack'!D:D,"未找到箱规")} -> 60 | Z46: =_xlfn.XLOOKUP(A46,'Product List'!B:B,'Product List'!M:M) -> Pet Supermarket,PSP | AA46: {=_xlfn.XLOOKUP(1,('Case Pack'!A:A=A46)*('Case Pack'!F:F<=TODAY()),'Case Pack'!G:G,"未找到箱规")} -> B | AB46: =V46/Y46 -> 0 | AC46: =_xlfn.XLOOKUP(AA46,'Case Type'!A:A,'Case Type'!H:H)*AB46 -> 0
A47: WJ-13 | B47: =_xlfn.XLOOKUP(A47,'Product List'!B:B,'Product List'!I:I) -> MINI/MOE CAMPING TENT HIDE | C47: 132 | D47: =SUMIFS(Purchase!F:F,Purchase!C:C,A47,Purchase!I:I,">"&$C$1,Purchase!V:V,"<>暂缓发货") -> 16584 | E47: =SUMIFS(Purchase!F:F,Purchase!C:C,A47,Purchase!J:J,">0",Purchase!I:I,">"&$C$1) -> 10068 | F47: =SUMIFS(Sales!E:E,Sales!C:C,A47,Sales!K:K,">"&$C$1) -> 9348 | G47: =SUMIFS(Sales!E:E,Sales!C:C,A47,Sales!K:K,">"&$C$1,Sales!L:L,">0") -> 9276 | H47: =C47+E47-G47-SUMIFS(Transfer!V:V,Transfer!O:O,A47)+SUMIFS(Transfer!W:W,Transfer!O:O,A47) -> 924 | I47: =D47-E47+SUMIFS(Transfer!V:V,Transfer!O:O,A47)-SUMIFS(Transfer!W:W,Transfer!O:O,A47) -> 6516 | J47: =SUMIFS(Purchase!F:F,Purchase!C:C,A47,Purchase!V:V,"暂缓发货") -> 0 | K47: =F47-G47 -> 72 | L47: =H47-K47 -> 852 | M47: =H47+I47-K47 -> 7368 | N47: =_xlfn.XLOOKUP(A47,'Product List'!B:B,'Product List'!F:F) -> A | O47: =SUMIF('Weekly Sales'!B:B,A47,'Weekly Sales'!R:R) -> 231 | P47: =IF(O47=0,999,ROUNDDOWN((L47)/O47,0)) -> 3 | Q47: =IF(O47=0,999,ROUNDDOWN((M47)/O47,0)) -> 31 | R47: =_xlfn.XLOOKUP(A47,'Product List'!B:B,'Product List'!P:P) -> 15 | S47: =IF(N47="A",6,IF(N47="B",5,2)) -> 6 | T47: =SUMIF('Weekly Sales'!B:B,A47,'Weekly Sales'!T:T) -> 1669.5 | U47: =_xlfn.XLOOKUP(A47,'Product List'!B:B,'Product List'!O:O) -> 500 | V47: =ROUNDUP(MAX(0,O47*(R47+S47+2)+T47-M47)/Y47,0)*Y47 -> 0 | W47: =_xlfn.XLOOKUP(A47,Sum_LA!A:A,Sum_LA!V:V) -> 0 | X47: =_xlfn.XLOOKUP(A47,Sum_HOU!A:A,Sum_HOU!V:V) -> 1422 | Y47: {=_xlfn.XLOOKUP(1,('Case Pack'!A:A=A47)*('Case Pack'!F:F<=TODAY()),'Case Pack'!D:D,"未找到箱规")} -> 18 | Z47: =_xlfn.XLOOKUP(A47,'Product List'!B:B,'Product List'!M:M) -> PSP, Petsmart, Pet Supermarket,Canada | AA47: {=_xlfn.XLOOKUP(1,('Case Pack'!A:A=A47)*('Case Pack'!F:F<=TODAY()),'Case Pack'!G:G,"未找到箱规")} -> B | AB47: =V47/Y47 -> 0 | AC47: =_xlfn.XLOOKUP(AA47,'Case Type'!A:A,'Case Type'!H:H)*AB47 -> 0
A48: WJ-14-B | B48: =_xlfn.XLOOKUP(A48,'Product List'!B:B,'Product List'!I:I) -> Little Devil Travel Cage | C48: 0 | D48: =SUMIFS(Purchase!F:F,Purchase!C:C,A48,Purchase!I:I,">"&$C$1,Purchase!V:V,"<>暂缓发货") -> 1260 | E48: =SUMIFS(Purchase!F:F,Purchase!C:C,A48,Purchase!J:J,">0",Purchase!I:I,">"&$C$1) -> 1260 | F48: =SUMIFS(Sales!E:E,Sales!C:C,A48,Sales!K:K,">"&$C$1) -> 612 | G48: =SUMIFS(Sales!E:E,Sales!C:C,A48,Sales!K:K,">"&$C$1,Sales!L:L,">0") -> 612 | H48: =C48+E48-G48-SUMIFS(Transfer!V:V,Transfer!O:O,A48)+SUMIFS(Transfer!W:W,Transfer!O:O,A48) -> 648 | I48: =D48-E48+SUMIFS(Transfer!V:V,Transfer!O:O,A48)-SUMIFS(Transfer!W:W,Transfer!O:O,A48) -> 0 | J48: =SUMIFS(Purchase!F:F,Purchase!C:C,A48,Purchase!V:V,"暂缓发货") -> 0 | K48: =F48-G48 -> 0 | L48: =H48-K48 -> 648 | M48: =H48+I48-K48 -> 648 | N48: =_xlfn.XLOOKUP(A48,'Product List'!B:B,'Product List'!F:F) -> C | O48: =SUMIF('Weekly Sales'!B:B,A48,'Weekly Sales'!R:R) -> 4 | P48: =IF(O48=0,999,ROUNDDOWN((L48)/O48,0)) -> 162 | Q48: =IF(O48=0,999,ROUNDDOWN((M48)/O48,0)) -> 162 | R48: =_xlfn.XLOOKUP(A48,'Product List'!B:B,'Product List'!P:P) -> 10 | S48: =IF(N48="A",6,IF(N48="B",5,2)) -> 2 | T48: =SUMIF('Weekly Sales'!B:B,A48,'Weekly Sales'!T:T) -> 0 | U48: =_xlfn.XLOOKUP(A48,'Product List'!B:B,'Product List'!O:O) -> 1000 | V48: =ROUNDUP(MAX(0,O48*(R48+S48+2)+T48-M48)/Y48,0)*Y48 -> 0 | W48: =_xlfn.XLOOKUP(A48,Sum_LA!A:A,Sum_LA!V:V) -> 0 | X48: =_xlfn.XLOOKUP(A48,Sum_HOU!A:A,Sum_HOU!V:V) -> 72 | Y48: {=_xlfn.XLOOKUP(1,('Case Pack'!A:A=A48)*('Case Pack'!F:F<=TODAY()),'Case Pack'!D:D,"未找到箱规")} -> 18 | Z48: =_xlfn.XLOOKUP(A48,'Product List'!B:B,'Product List'!M:M) -> PetcoMX,PSP，Canada | AA48: {=_xlfn.XLOOKUP(1,('Case Pack'!A:A=A48)*('Case Pack'!F:F<=TODAY()),'Case Pack'!G:G,"未找到箱规")} -> C | AB48: =V48/Y48 -> 0 | AC48: =_xlfn.XLOOKUP(AA48,'Case Type'!A:A,'Case Type'!H:H)*AB48 -> 0
... A62: ZM1.2-RD-GN | B62: =_xlfn.XLOOKUP(A62,'Product List'!B:B,'Product List'!I:I) -> MINI/MOE SMALL ANIMAL BEDDING PAPER FLK XMAS CRAN/MATCHA 1EA | C62: 0 | D62: =SUMIFS(Purchase!F:F,Purchase!C:C,A62,Purchase!I:I,">"&$C$1,Purchase!V:V,"<>暂缓发货") -> 1260 | E62: =SUMIFS(Purchase!F:F,Purchase!C:C,A62,Purchase!J:J,">0",Purchase!I:I,">"&$C$1) -> 1260 | F62: =SUMIFS(Sales!E:E,Sales!C:C,A62,Sales!K:K,">"&$C$1) -> 630 | G62: =SUMIFS(Sales!E:E,Sales!C:C,A62,Sales!K:K,">"&$C$1,Sales!L:L,">0") -> 630 | H62: =C62+E62-G62-SUMIFS(Transfer!V:V,Transfer!O:O,A62)+SUMIFS(Transfer!W:W,Transfer!O:O,A62) -> 630 | I62: =D62-E62+SUMIFS(Transfer!V:V,Transfer!O:O,A62)-SUMIFS(Transfer!W:W,Transfer!O:O,A62) -> 0 | J62: =SUMIFS(Purchase!F:F,Purchase!C:C,A62,Purchase!V:V,"暂缓发货") -> 0 | K62: =F62-G62 -> 0 | L62: =H62-K62 -> 630 | M62: =H62+I62-K62 -> 630 | N62: =_xlfn.XLOOKUP(A62,'Product List'!B:B,'Product List'!F:F) -> C | O62: =SUMIF('Weekly Sales'!B:B,A62,'Weekly Sales'!R:R) -> 0.33333333 | P62: =IF(O62=0,999,ROUNDDOWN((L62)/O62,0)) -> 1890 | Q62: =IF(O62=0,999,ROUNDDOWN((M62)/O62,0)) -> 1890 | R62: =_xlfn.XLOOKUP(A62,'Product List'!B:B,'Product List'!P:P) -> 10 | S62: =IF(N62="A",6,IF(N62="B",5,2)) -> 2 | T62: =SUMIF('Weekly Sales'!B:B,A62,'Weekly Sales'!T:T) -> 0 | U62: =_xlfn.XLOOKUP(A62,'Product List'!B:B,'Product List'!O:O) -> 1000 | V62: =ROUNDUP(MAX(0,O62*(R62+S62+2)+T62-M62)/Y62,0)*Y62 -> 0 | W62: =_xlfn.XLOOKUP(A62,Sum_LA!A:A,Sum_LA!V:V) -> 0 | X62: =_xlfn.XLOOKUP(A62,Sum_HOU!A:A,Sum_HOU!V:V) -> 14 | Y62: {=_xlfn.XLOOKUP(1,('Case Pack'!A:A=A62)*('Case Pack'!F:F<=TODAY()),'Case Pack'!D:D,"未找到箱规")} -> 14 | Z62: =_xlfn.XLOOKUP(A62,'Product List'!B:B,'Product List'!M:M) -> PSP | AA62: {=_xlfn.XLOOKUP(1,('Case Pack'!A:A=A62)*('Case Pack'!F:F<=TODAY()),'Case Pack'!G:G,"未找到箱规")} -> C | AB62: =V62/Y62 -> 0 | AC62: =_xlfn.XLOOKUP(AA62,'Case Type'!A:A,'Case Type'!H:H)*AB62 -> 0

Sheet Sum_LA
A1: Item Code | B1: Product Name | C1: 46125 | D1: Purchased | E1: Arrived | F1: Sales Order | G1: Cons. | H1: OH Stock | I1: In-Transit | J1: On Hold | K1: Alloc. | L1: Avail. | M1: Total Stock | N1: ABC | O1: Wkly Fcst. | P1: OH TO | Q1: Inv. TO | R1: LT | S1: SS | T1: Extra | U1: MOQ | V1: Plan | W1: Case Pack | X1: Channel | Y1: Case Type | Z1: Case Qty | AA1: CBM
A2: BOBO22-GN | B2: =_xlfn.XLOOKUP(A2,'Product List'!B:B,'Product List'!I:I) -> MINI/MOE SILENT CRSTL RUN WHEEL LG 8.5-Green | C2: 0 | D2: =SUMIFS(Purchase!F:F,Purchase!C:C,A2,Purchase!I:I,">"&$C$1,Purchase!V:V,"<>暂缓发货",Purchase!U:U,"LA") -> 744 | E2: =SUMIFS(Purchase!F:F,Purchase!C:C,A2,Purchase!J:J,">0",Purchase!I:I,">"&$C$1,Purchase!U:U,"LA") -> 744 | F2: =SUMIFS(Sales!E:E,Sales!C:C,A2,Sales!K:K,">"&$C$1,Sales!I:I,"LA") -> 376 | G2: =SUMIFS(Sales!E:E,Sales!C:C,A2,Sales!K:K,">"&$C$1,Sales!L:L,">0",Sales!I:I,"LA") -> 368 | H2: =C2+E2-G2+SUMIFS(Transfer!W:W,Transfer!O:O,A2,Transfer!Q:Q,"LA",Transfer!U:U,">"&$C$1)-SUMIFS(Transfer!V:V,Transfer!O:O,A2,Transfer!P:P,"LA",Transfer!T:T,">"&$C$1) -> 376 | I2: =D2-E2+SUMIFS(Transfer!V:V,Transfer!O:O,A2,Transfer!Q:Q,"LA")-SUMIFS(Transfer!W:W,Transfer!O:O,A2,Transfer!Q:Q,"LA") -> 0 | J2: =SUMIFS(Purchase!F:F,Purchase!C:C,A2,Purchase!V:V,"暂缓发货",Purchase!U:U,"LA") -> 0 | K2: =F2-G2 -> 8 | L2: =H2-K2 -> 368 | M2: =H2+I2-K2 -> 368 | N2: =_xlfn.XLOOKUP(A2,'Product List'!B:B,'Product List'!F:F) -> C | O2: =SUMIFS('Weekly Sales'!R:R,'Weekly Sales'!B:B,A2,'Weekly Sales'!U:U,"LA") -> 0 | P2: =IF(O2=0,999,ROUNDDOWN((L2)/O2,0)) -> 999 | Q2: =IF(O2=0,999,ROUNDDOWN((M2)/O2,0)) -> 999 | R2: =_xlfn.XLOOKUP(A2,'Product List'!B:B,'Product List'!P:P) -> 10 | S2: =IF(N2="A",6,IF(N2="B",5,2)) -> 2 | T2: =SUMIFS('Weekly Sales'!T:T,'Weekly Sales'!B:B,A2,'Weekly Sales'!U:U,"LA") -> 0 | U2: =_xlfn.XLOOKUP(A2,'Product List'!B:B,'Product List'!O:O) -> 1000 | V2: =ROUNDUP(MAX(0,O2*(R2+S2+2)+T2-M2)/W2,0)*W2 -> 0 | W2: {=_xlfn.XLOOKUP(1,('Case Pack'!A:A=A2)*('Case Pack'!F:F<=TODAY()),'Case Pack'!D:D,"未找到箱规")} -> 16 | X2: =_xlfn.XLOOKUP(A2,'Product List'!B:B,'Product List'!M:M) -> PSP | Y2: {=_xlfn.XLOOKUP(1,('Case Pack'!A:A=A2)*('Case Pack'!F:F<=TODAY()),'Case Pack'!G:G,"未找到箱规")} -> C | Z2: =V2/W2 -> 0 | AA2: =_xlfn.XLOOKUP(Y2,'Case Type'!A:A,'Case Type'!H:H)*Z2 -> 0
A3: BOBO22-WH | B3: =_xlfn.XLOOKUP(A3,'Product List'!B:B,'Product List'!I:I) -> MINI/MOE SILENT CRSTL RUN WHEEL LG 8.5-White | C3: 412 | D3: =SUMIFS(Purchase!F:F,Purchase!C:C,A3,Purchase!I:I,">"&$C$1,Purchase!V:V,"<>暂缓发货",Purchase!U:U,"LA") -> 7336 | E3: =SUMIFS(Purchase!F:F,Purchase!C:C,A3,Purchase!J:J,">0",Purchase!I:I,">"&$C$1,Purchase!U:U,"LA") -> 7336 | F3: =SUMIFS(Sales!E:E,Sales!C:C,A3,Sales!K:K,">"&$C$1,Sales!I:I,"LA") -> 4748 | G3: =SUMIFS(Sales!E:E,Sales!C:C,A3,Sales!K:K,">"&$C$1,Sales!L:L,">0",Sales!I:I,"LA") -> 3876 | H3: =C3+E3-G3+SUMIFS(Transfer!W:W,Transfer!O:O,A3,Transfer!Q:Q,"LA",Transfer!U:U,">"&$C$1)-SUMIFS(Transfer!V:V,Transfer!O:O,A3,Transfer!P:P,"LA",Transfer!T:T,">"&$C$1) -> 3872 | I3: =D3-E3+SUMIFS(Transfer!V:V,Transfer!O:O,A3,Transfer!Q:Q,"LA")-SUMIFS(Transfer!W:W,Transfer!O:O,A3,Transfer!Q:Q,"LA") -> 0 | J3: =SUMIFS(Purchase!F:F,Purchase!C:C,A3,Purchase!V:V,"暂缓发货",Purchase!U:U,"LA") -> 1352 | K3: =F3-G3 -> 872 | L3: =H3-K3 -> 3000 | M3: =H3+I3-K3 -> 3000 | N3: =_xlfn.XLOOKUP(A3,'Product List'!B:B,'Product List'!F:F) -> A | O3: =SUMIFS('Weekly Sales'!R:R,'Weekly Sales'!B:B,A3,'Weekly Sales'!U:U,"LA") -> 95.5 | P3: =IF(O3=0,999,ROUNDDOWN((L3)/O3,0)) -> 31 | Q3: =IF(O3=0,999,ROUNDDOWN((M3)/O3,0)) -> 31 | R3: =_xlfn.XLOOKUP(A3,'Product List'!B:B,'Product List'!P:P) -> 10 | S3: =IF(N3="A",6,IF(N3="B",5,2)) -> 6 | T3: =SUMIFS('Weekly Sales'!T:T,'Weekly Sales'!B:B,A3,'Weekly Sales'!U:U,"LA") -> 620.75 | U3: =_xlfn.XLOOKUP(A3,'Product List'!B:B,'Product List'!O:O) -> 1000 | V3: =ROUNDUP(MAX(0,O3*(R3+S3+2)+T3-M3)/W3,0)*W3 -> 0 | W3: {=_xlfn.XLOOKUP(1,('Case Pack'!A:A=A3)*('Case Pack'!F:F<=TODAY()),'Case Pack'!D:D,"未找到箱规")} -> 16 | X3: =_xlfn.XLOOKUP(A3,'Product List'!B:B,'Product List'!M:M) -> PetcoUS, PetcoMX, Pet Supermarket，PSP | Y3: {=_xlfn.XLOOKUP(1,('Case Pack'!A:A=A3)*('Case Pack'!F:F<=TODAY()),'Case Pack'!G:G,"未找到箱规")} -> C | Z3: =V3/W3 -> 0 | AA3: =_xlfn.XLOOKUP(Y3,'Case Type'!A:A,'Case Type'!H:H)*Z3 -> 0
A4: CFDL1090-BR | B4: =_xlfn.XLOOKUP(A4,'Product List'!B:B,'Product List'!I:I) -> MINI/MOE SMALL ANIMAL BEDDING CRINKLE PAPER BROWN 1EA | C4: 0 | D4: =SUMIFS(Purchase!F:F,Purchase!C:C,A4,Purchase!I:I,">"&$C$1,Purchase!V:V,"<>暂缓发货",Purchase!U:U,"LA") -> 1260 | E4: =SUMIFS(Purchase!F:F,Purchase!C:C,A4,Purchase!J:J,">0",Purchase!I:I,">"&$C$1,Purchase!U:U,"LA") -> 1260 | F4: =SUMIFS(Sales!E:E,Sales!C:C,A4,Sales!K:K,">"&$C$1,Sales!I:I,"LA") -> 630 | G4: =SUMIFS(Sales!E:E,Sales!C:C,A4,Sales!K:K,">"&$C$1,Sales!L:L,">0",Sales!I:I,"LA") -> 630 | H4: =C4+E4-G4+SUMIFS(Transfer!W:W,Transfer!O:O,A4,Transfer!Q:Q,"LA",Transfer!U:U,">"&$C$1)-SUMIFS(Transfer!V:V,Transfer!O:O,A4,Transfer!P:P,"LA",Transfer!T:T,">"&$C$1) -> 630 | I4: =D4-E4+SUMIFS(Transfer!V:V,Transfer!O:O,A4,Transfer!Q:Q,"LA")-SUMIFS(Transfer!W:W,Transfer!O:O,A4,Transfer!Q:Q,"LA") -> 0 | J4: =SUMIFS(Purchase!F:F,Purchase!C:C,A4,Purchase!V:V,"暂缓发货",Purchase!U:U,"LA") -> 0 | K4: =F4-G4 -> 0 | L4: =H4-K4 -> 630 | M4: =H4+I4-K4 -> 630 | N4: =_xlfn.XLOOKUP(A4,'Product List'!B:B,'Product List'!F:F) -> C | O4: =SUMIFS('Weekly Sales'!R:R,'Weekly Sales'!B:B,A4,'Weekly Sales'!U:U,"LA") -> 0 | P4: =IF(O4=0,999,ROUNDDOWN((L4)/O4,0)) -> 999 | Q4: =IF(O4=0,999,ROUNDDOWN((M4)/O4,0)) -> 999 | R4: =_xlfn.XLOOKUP(A4,'Product List'!B:B,'Product List'!P:P) -> 10 | S4: =IF(N4="A",6,IF(N4="B",5,2)) -> 2 | T4: =SUMIFS('Weekly Sales'!T:T,'Weekly Sales'!B:B,A4,'Weekly Sales'!U:U,"LA") -> 0 | U4: =_xlfn.XLOOKUP(A4,'Product List'!B:B,'Product List'!O:O) -> 1000 | V4: =ROUNDUP(MAX(0,O4*(R4+S4+2)+T4-M4)/W4,0)*W4 -> 0 | W4: {=_xlfn.XLOOKUP(1,('Case Pack'!A:A=A4)*('Case Pack'!F:F<=TODAY()),'Case Pack'!D:D,"未找到箱规")} -> 30 | X4: =_xlfn.XLOOKUP(A4,'Product List'!B:B,'Product List'!M:M) -> PSP | Y4: {=_xlfn.XLOOKUP(1,('Case Pack'!A:A=A4)*('Case Pack'!F:F<=TODAY()),'Case Pack'!G:G,"未找到箱规")} -> A | Z4: =V4/W4 -> 0 | AA4: =_xlfn.XLOOKUP(Y4,'Case Type'!A:A,'Case Type'!H:H)*Z4 -> 0
A5: CFDL1090-PK | B5: =_xlfn.XLOOKUP(A5,'Product List'!B:B,'Product List'!I:I) -> MINI/MOE SMALL ANIMAL BEDDING PAPER PEBBLES PSTCH/CREAM 1EA | C5: 0 | D5: =SUMIFS(Purchase!F:F,Purchase!C:C,A5,Purchase!I:I,">"&$C$1,Purchase!V:V,"<>暂缓发货",Purchase!U:U,"LA") -> 1260 | E5: =SUMIFS(Purchase!F:F,Purchase!C:C,A5,Purchase!J:J,">0",Purchase!I:I,">"&$C$1,Purchase!U:U,"LA") -> 1260 | F5: =SUMIFS(Sales!E:E,Sales!C:C,A5,Sales!K:K,">"&$C$1,Sales!I:I,"LA") -> 630 | G5: =SUMIFS(Sales!E:E,Sales!C:C,A5,Sales!K:K,">"&$C$1,Sales!L:L,">0",Sales!I:I,"LA") -> 630 | H5: =C5+E5-G5+SUMIFS(Transfer!W:W,Transfer!O:O,A5,Transfer!Q:Q,"LA",Transfer!U:U,">"&$C$1)-SUMIFS(Transfer!V:V,Transfer!O:O,A5,Transfer!P:P,"LA",Transfer!T:T,">"&$C$1) -> 630 | I5: =D5-E5+SUMIFS(Transfer!V:V,Transfer!O:O,A5,Transfer!Q:Q,"LA")-SUMIFS(Transfer!W:W,Transfer!O:O,A5,Transfer!Q:Q,"LA") -> 0 | J5: =SUMIFS(Purchase!F:F,Purchase!C:C,A5,Purchase!V:V,"暂缓发货",Purchase!U:U,"LA") -> 0 | K5: =F5-G5 -> 0 | L5: =H5-K5 -> 630 | M5: =H5+I5-K5 -> 630 | N5: =_xlfn.XLOOKUP(A5,'Product List'!B:B,'Product List'!F:F) -> C | O5: =SUMIFS('Weekly Sales'!R:R,'Weekly Sales'!B:B,A5,'Weekly Sales'!U:U,"LA") -> 0 | P5: =IF(O5=0,999,ROUNDDOWN((L5)/O5,0)) -> 999 | Q5: =IF(O5=0,999,ROUNDDOWN((M5)/O5,0)) -> 999 | R5: =_xlfn.XLOOKUP(A5,'Product List'!B:B,'Product List'!P:P) -> 10 | S5: =IF(N5="A",6,IF(N5="B",5,2)) -> 2 | T5: =SUMIFS('Weekly Sales'!T:T,'Weekly Sales'!B:B,A5,'Weekly Sales'!U:U,"LA") -> 0 | U5: =_xlfn.XLOOKUP(A5,'Product List'!B:B,'Product List'!O:O) -> 1000 | V5: =ROUNDUP(MAX(0,O5*(R5+S5+2)+T5-M5)/W5,0)*W5 -> 0 | W5: {=_xlfn.XLOOKUP(1,('Case Pack'!A:A=A5)*('Case Pack'!F:F<=TODAY()),'Case Pack'!D:D,"未找到箱规")} -> 30 | X5: =_xlfn.XLOOKUP(A5,'Product List'!B:B,'Product List'!M:M) -> PSP | Y5: {=_xlfn.XLOOKUP(1,('Case Pack'!A:A=A5)*('Case Pack'!F:F<=TODAY()),'Case Pack'!G:G,"未找到箱规")} -> A | Z5: =V5/W5 -> 0 | AA5: =_xlfn.XLOOKUP(Y5,'Case Type'!A:A,'Case Type'!H:H)*Z5 -> 0
